Workbook
Name _CCC10: #REF!
Name _CCC2: #REF!
Name _CCC3: #REF!
Name _CCC4: #REF!
Name _CCC5: #REF!
Name _CCC6: #REF!
Name _CCC7: #REF!
Name _CCC8: #REF!
Name _CCC9: #REF!
Name _mo12: #REF!
Name _MO5: #REF!
Name _mo7: #REF!
Name _NSA1: #REF!
Name _NSA10: #REF!
Name _NSA2: #REF!
Name _NSA3: #REF!
Name _NSA4: #REF!
Name _NSA5: #REF!
Name _NSA6: #REF!
Name _NSA7: #REF!
Name _NSA8: #REF!
Name _NSA9: #REF!
Name _X1: '[1]06-00'!#REF!
Name _X11: #REF!
Name a: #REF!
Name Actual_PtaxandERAF_Report: #REF!
Name Analysis_Actuals: '[2] Analysis for Actuals'!$B$10:$J$81
Name azaz: #REF!
Name CALGRANT_FALLSPRING: #REF!
Name CCC_BASE_92: #REF!
Name CCC_BASE_93: #REF!
Name CCC_BASE_94: #REF!
Name CO_APPORT_REV_9: #REF!
Name CO_NET_LR_86: #REF!
Name CO_NET_LR_87: #REF!
Name CO_NET_LR_88: #REF!
Name CO_NET_LR_89: #REF!
Name CO_NET_LR_90: #REF!
Name CO_P98_LR_93: #REF!
Name CO_P98_LR_94: #REF!
Name CO_SE_SHARE_92: #REF!
Name CO_SE_SHARE_93: #REF!
Name CO_SE_SHARE_94: #REF!
Name CO_SE_TR_91: #REF!
Name CO_SE_TR_92: #REF!
Name CO_SE_TR_93: #REF!
Name CO_SE_TR_94: #REF!
Name CO_SHIFT_92: #REF!
Name CO_SHIFT_93: #REF!
Name CO_SHIFT_94: #REF!
Name CO_TR_91: #REF!
Name CO_TR_92: #REF!
Name CO_TR_93: #REF!
Name CO_TR_94: #REF!
Name COUNTY_PTAX: '[3]1d.County ptax11-15-2015'!$D$2:$AP$247
Name COUNTYERAFREPORT: [4]!NEWERAFModPtax6[[Left Blank]:[Total Positive ERAF to Distribute]]
Name CountyTOT_PTR_A: #REF!
Name d: #REF!
Name Data_Actuals: '[2]EF2016-2017P3 (Actuals)'!$B$8:$M$79
Name Database_MI: #REF!

Sheet 1. Data Dictionary
A1: Data Dictionary
A2: Factor | B2: Current Law Definition | C2: Changes to Definition in this Simulation
A3: Noncredit FTES (excluding CDCP noncredit FTES). | B3: The funding rate is unchanged from current practice. For purposes of our estimates, we calculate growth from prior year FTES, adding any restoration that occurs. | C3: No Change
A4: CDCP noncredit FTES | B4: The funding rate is unchanged from current practice. For purposes of our estimates, we calculate growth from prior year FTES, adding any restoration that occurs. | C4: No Change
A5: Base Allocation (70%)
A6: Credit Full-Time Equivalent Students (FTES) | B6: Three-year rolling average of funded FTES. Specifically, average equal to the sum of the annually funded credit FTES from the current year, the prior year, and the year prior to the prior year, all divided by three. Credit FTES for these purposes excludes FTES of special admit students and inmates in correctional facilities. | C6: No Change
A7: Basic Allocation | B7: Number of colleges and comprehensive centers in the community college district (with funding consistent with the basic allocation formula established by the Board of Governors as of the 2015-16 fiscal year). | C7: No Change
A8: Special Admit Students FTES | B8: Funded FTES generated by students who meet the requirements of ECS 76002, 76003, and 76004 | C8: No Change
A9: Students in Correctional Facilities FTES | B9: Funded FTES generated by students who meet the requirements of ECS 84810.5(a). | C9: No Change
A10: Supplemental Allocation (20%)
A11: Pell Grant Recipients | B11: Headcount of all students in the prior year who were recipients of financial aid under the Federal Pell Grant program. | C11: No Change
A12: AB 540 Students | B12: Headcount of all students in the prior year who were granted an exemption from nonresident tuition pursuant to ECS 68130.5. | C12: No Change
A13: California College Promise Grant Recipients | B13: Headcount of all students in the prior year who were received a fee waiver pursuant to Section 76300. | C13: No Change
A14: Student Success Allocation (10%)
A15: Associate Degrees for Transfer | B15: Count of all Chancellor's Office approved associate degrees for transfer granted based on prior year data. | C15: Use a three year average of 2016-17, 2017-18, and 2018-19 (projected). Count only the highest outcome a student attains of ADT, associate degree, baccalaureate degree, and credit certificate (16 units or greater). Count the outcome only if a student took 9 or more units in the district in the academic year of the award.
A16: Associate Degrees | B16: Count of all Chancellor's Office approved associate degrees granted (excluding associate degrees for transfer granted) based on prior year data. | C16: Use a three year average of 2016-17, 2017-18, and 2018-19 (projected). Count only the highest outcome a student attains of ADT, associate degree, baccalaureate degree, and credit certificate (16 units or greater). Count the outcome only if a student took 9 or more units in the district in the academic year of the award.
A17: Baccalaureate Degrees | B17: Count of all Chancellor's Office approved baccalaureate degrees granted based on prior year data. | C17: Use a three year average of 2016-17, 2017-18, and 2018-19 (projected). Count only the highest outcome a student attains of ADT, associate degree, baccalaureate degree, and credit certificate (16 units or greater). Count the outcome only if a student took 9 or more units in the district in the academic year of the award.
A18: Credit Certificates | B18: Count of all Chancellor's Office approved credit certificates requiring 16 or more units granted based on prior year data. | C18: Use a three year average of 2016-17, 2017-18, and 2018-19 (projected). Count only the highest outcome a student attains of ADT, associate degree, baccalaureate degree, and credit certificate (16 units or greater). Count the outcome only if a student took 9 or more units in the district in the academic year of the award.
A19: Completion of Transfer-Level Mathematics and English | B19: Count of all first-time students who successfully completes both transfer-level mathematics and English courses within the same district within the first academic year (summer, fall, and spring) of enrollment based on prior year data. | C19: Use a three year average of 2016-17, 2017-18, and 2018-19 (projected).
A20: Completion of Nine CTE Units | B20: Count of all students who successfully completed nine or more career technical education (CTE) units within the same district based on prior year data. CTE courses are SAM A, B, C courses or all courses with a CTE TOP Code. | C20: Use a three year average of 2016-17, 2017-18, and 2018-19 (projected).
A21: Successful Transfer to Four-Year University | B21: Count of all students who successfully transferred to a four-year university based on prior year data. | C21: The student has completed 12 or more semester units, or the equivalent, in the community college district in the year prior to the prior year and has an enrollment record in the prior prior year. Use a three year average of 2016-17, 2017-18, and 2018-19 (projected).
A22: Regional Living Wage | B22: Count of all students who obtained a regional living wage within one year of community college completion based on prior year data. | C22: Use a three year average of 2016-17, 2017-18, and 2018-19 (projected).
A23: Equity Component
A24: Pell Grant Recipients | B24: Outcomes for all students who received financial aid under the Federal Pell Grant program. | C24: Use a three year average of 2016-17, 2017-18, and 2018-19 (projected).
A25: California College Promise Grant Recipients | B25: Outcomes for all students who received a fee waiver pursuant to Section 76300. | C25: Use a three year average of 2016-17, 2017-18, and 2018-19 (projected).

Sheet 2. Weighting
A1: Total SCFF 2019-20
A3: Total SCFF Target for 19-20 (before Hold Harmless) | B3: 7.4972375e+09 | G3: TCR 19-20 Calculated | H3: ='3. HH-Total'!N78 -> 7.3370407e+09
A4: Base NonCredit and CDCP | B4: =SUM(C15:C16) -> 3.4120934e+08 | G4: Hold Harmless Calculated | H4: ='3. HH-Total'!M78 -> 2.4845495e+08
B5: =B3-B4 -> 7.1560281e+09 | G5: TCR 19-20 DOF Enacted | H5: 7.3370407e+09
A6: Base | B6: =B$5*C6 -> 5.0092197e+09 | C6: 0.7 | G6: Hold Harmless DOF Enacted | H6: 1.8262402e+08
A7: Supplemental | B7: =B$5*C7 -> 1.4312056e+09 | C7: 0.2
A8: Success | B8: =B$5*C8 -> 7.1560281e+08 | C8: 0.1
A9: COLA 19-20 | B9: 0.0326
A13: CCC Funding Formula Factors for 2019-20 70/20/10
B14: Counts | C14: Funding | E14: 2019-20 Rates
A15: Non-Credit FTES (Rate from DOF) | B15: ='5a. Base Counts'!C78 -> 35123.935 | C15: =B15*E15 -> 1.1885435e+08 | E15: 3383.8562
A16: Non-Credit CDCP FTES (Rate from DOF) | B16: ='5a. Base Counts'!D78 -> 39437.772 | C16: =B16*E16 -> 2.2235499e+08 | E16: 5638.1225
A17: Base Allocation: 70%
B18: Counts | C18: Funding | E18: 2019-20 Rates
A19: Basic Allocation | C19: ='5. Base Allocation'!B78 -> 6.2872988e+08
A20: Credit FTES | B20: ='5a. Base Counts'!B78 -> 1003674 | C20: =C25+C26 -> 4.1491829e+09 | E20: 4123.5
A21: Credit Special Admits and Students in Correctional Facilities FTES (Rates from DOF) | B21: ='5a. Base Counts'!E78 -> 40889.824 | C21: ='Differential Districts'!F34 -> 2.3104445e+08 | E21: 5638.1225
A22: Total calculated | B22: =SUM(B20:B21) -> 1044563.8 | C22: =SUM(C19:C21) -> 5.0089572e+09
A23: Total Base per formula | C23: =B6 -> 5.0092197e+09
A24: Credit FTES Total (regular and differential) | C24: =C23-(C19+C21) -> 4.1494453e+09
A25: Differential districts | B25: ='Differential Districts'!E15 -> 108631.63 | C25: ='Differential Districts'!F15 -> 4.5847561e+08
A26: Non differential districts credit FTES | B26: =B20-B25 -> 895042.38 | C26: =B26*E20 -> 3.6907073e+09
A28: Supplemental Allocation: 20%
B30: Points | C30: Total Counts1 | D30: Total Points | E30: Total Dollars
A31: Supplemental Metrics | B31: (a) | C31: (b) | D31: (c) = (a) * (b) | E31: (d) = (c) * B37
A32: Pell Grant | B32: 1 | C32: ='6a. Supp Counts'!F78 -> 437357 | D32: =B32*C32 -> 437357 | E32: =D32*B$38 -> 4.2545912e+08
A33: AB 540 Students | B33: 1 | C33: ='6a. Supp Counts'!G78 -> 57994 | D33: =B33*C33 -> 57994 | E33: =D33*B$38 -> 56416329
A34: California Promise Grant Students | B34: 1 | C34: ='6a. Supp Counts'!H78 -> 975878 | D34: =B34*C34 -> 975878 | E34: =D34*B$38 -> 9.4933017e+08
A35: Total calculated | E35: =E32+E33+E34 -> 1.4312056e+09
A36: Total per formula | B36: =SUM(B32:B34) -> 3 | C36: =SUM(C32:C34) -> 1471229 | D36: =SUM(D32:D34) -> 1471229 | E36: =B7 -> 1.4312056e+09
A38: Supplemental Rate Per Point | B38: =E36/D36 -> 972.79596
A40: Student Success Incentive Allocation: 10%
B41: Points | C41: Total Counts1 | D41: Total Points | E41: Total Dollars
B42: (a) | C42: (b) | D42: (c) = (a) * (b) | E42: (d) = (c) * B54
A43: Success Metrics
A44: Associate degree for transfer | B44: 4 | C44: ='7b. Success proj 1819'!B76 -> 51998 | D44: =B44*C44 -> 207992 | E44: =D44*B$55 -> 1.0394862e+08
A45: Associate degree | B45: 3 | C45: ='7b. Success proj 1819'!C76 -> 62587 | D45: =B45*C45 -> 187761 | E45: =D45*B$55 -> 93837731
A46: Bachelor degree | B46: 3 | C46: ='7b. Success proj 1819'!D76 -> 212 | D46: =B46*C46 -> 636 | E46: =D46*B$55 -> 317855.13
A47: Credit certificates requiring 16+ units | B47: 2 | C47: ='7b. Success proj 1819'!E76 -> 23172 | D47: =B47*C47 -> 46344 | E47: =D47*B$55 -> 23161443
A48: Completion of transfer-level math and English | B48: 2 | C48: ='7b. Success proj 1819'!F76 -> 28604 | D48: =B48*C48 -> 57208 | E48: =D48*B$55 -> 28590969
...

Sheet Differential Districts
B1: 2017-18 rate | D1: 2019-20 Rate
A2: Credit FTES | B2: ='2. Weighting'!B85 -> 3727 | D2: ='2. Weighting'!E20 -> 4123.5
A3: Districts with Differential Rates | B3: 2017-18 per SCFF Statute | C3: 2017-18 rate as % of regular 2018 rate | D3: New Rate (2019-20 adjusted) | E3: 3-yr avg Credit FTES | F3: Differential total $ credit FTES with 1920 rates
A5: Foothill-De Anza | B5: 3745 | C5: =B5/B$2 -> 1.0048296 | D5: =D$2*C5 -> 4143.4149 | E5: ='5a. Base Counts'!B22 -> 21924.874 | F5: =D5*E5 -> 90843852
A6: Lake Tahoe | B6: 3817.5887 | C6: =B6/B$2 -> 1.0243061 | D6: =D$2*C6 -> 4223.7261 | E6: ='5a. Base Counts'!B29 -> 1595.5535 | F6: =D6*E6 -> 6739180.7
A7: Lassen | B7: 3794.1259 | C7: =B7/B$2 -> 1.0180107 | D7: =D$2*C7 -> 4197.7672 | E7: ='5a. Base Counts'!B30 -> 755.73115 | F7: =D7*E7 -> 3172383.4
A8: Marin | B8: 4261.4665 | C8: =B8/B$2 -> 1.1434039 | D8: =D$2*C8 -> 4714.8261 | E8: ='5a. Base Counts'!B34 -> 2960.3378 | F8: =D8*E8 -> 13957478
A9: MiraCosta | B9: 3733.8826 | C9: =B9/B$2 -> 1.0018467 | D9: =D$2*C9 -> 4131.1148 | E9: ='5a. Base Counts'!B37 -> 9235.1822 | F9: =D9*E9 -> 38151598
A10: San Francisco | B10: 3756.2121 | C10: =B10/B$2 -> 1.007838 | D10: =D$2*C10 -> 4155.8199 | E10: ='5a. Base Counts'!B54 -> 16320.546 | F10: =D10*E10 -> 67825248
A11: San Jose-Evergreen | B11: 3743.7854 | C11: =B11/B$2 -> 1.0045037 | D11: =D$2*C11 -> 4142.0711 | E11: ='5a. Base Counts'!B56 -> 11791.251 | F11: =D11*E11 -> 48840201
A12: Santa Monica | B12: 3776.4503 | C12: =B12/B$2 -> 1.0132681 | D12: =D$2*C12 -> 4178.2111 | E12: ='5a. Base Counts'!B61 -> 18684.956 | F12: =D12*E12 -> 78069689
A13: South Orange | B13: 3825.5597 | C13: =B13/B$2 -> 1.0264448 | D13: =D$2*C13 -> 4232.5451 | E13: ='5a. Base Counts'!B68 -> 22488.816 | F13: =D13*E13 -> 95184925
A14: West Kern | B14: 4934.025 | C14: =B14/B$2 -> 1.3238597 | D14: =D$2*C14 -> 5458.9354 | E14: ='5a. Base Counts'!B74 -> 2874.3797 | F14: =D14*E14 -> 15691053
E15: =SUM(E5:E14) -> 108631.63 | F15: =SUM(F5:F14) -> 4.5847561e+08
D17: 2019-20 Rate | E17: 3-yr avg Special admit/Students in Correctional FTES | F17: Differential total $ special admit and students in correctional FTES with 1920 rates
A18: Special Admit/Students in Correctional Facilities | D18: ='2. Weighting'!E21 -> 5638.1225
A19: Districts with Differential Rates
A21: Foothill-De Anza | C21: =C5 -> 1.0048296 | D21: =D$18*C21 -> 5665.3525 | E21: ='5a. Base Counts'!E22 -> 835.09333 | F21: =D21*E21 -> 4731098.1
A22: Lake Tahoe | C22: =C6 -> 1.0243061 | D22: =D$18*C22 -> 5775.1631 | E22: ='5a. Base Counts'!E29 -> 132.84987 | F22: =D22*E22 -> 767229.66
A23: Lassen | C23: =C7 -> 1.0180107 | D23: =D$18*C23 -> 5739.6691 | E23: ='5a. Base Counts'!E30 -> 899.75536 | F23: =D23*E23 -> 5164298
A24: Marin | C24: =C8 -> 1.1434039 | D24: =D$18*C24 -> 6446.6514 | E24: ='5a. Base Counts'!E34 -> 143.66333 | F24: =D24*E24 -> 926147.43
A25: MiraCosta | C25: =C9 -> 1.0018467 | D25: =D$18*C25 -> 5648.5343 | E25: ='5a. Base Counts'!E37 -> 103.71 | F25: =D25*E25 -> 585809.49
A26: San Francisco | C26: =C10 -> 1.007838 | D26: =D$18*C26 -> 5682.3139 | E26: ='5a. Base Counts'!E54 -> 312.91 | F26: =D26*E26 -> 1778052.8
A27: San Jose-Evergreen | C27: =C11 -> 1.0045037 | D27: =D$18*C27 -> 5663.515 | E27: ='5a. Base Counts'!E56 -> 269.75333 | F27: =D27*E27 -> 1527752.1
A28: Santa Monica | C28: =C12 -> 1.0132681 | D28: =D$18*C28 -> 5712.9298 | E28: ='5a. Base Counts'!E61 -> 266.29667 | F28: =D28*E28 -> 1521334.2
A29: South Orange | C29: =C13 -> 1.0264448 | D29: =D$18*C29 -> 5787.2214 | E29: ='5a. Base Counts'!E68 -> 821.27 | F29: =D29*E29 -> 4752871.3
A30: West Kern | C30: =C14 -> 1.3238597 | D30: =D$18*C30 -> 7464.083 | E30: ='5a. Base Counts'!E74 -> 49.299305 | F30: =D30*E30 -> 367974.11
E31: =SUM(E21:E30) -> 3834.6012 | F31: =SUM(F21:F30) -> 22122567
A33: Special Admit students nondifferential | E33: ='5a. Base Counts'!E78-'Differential Districts'!E31 -> 37055.223 | F33: =E33*D18 -> 2.0892189e+08
A34: Total differential and nondifferential | F34: =SUM(F31,F33) -> 2.3104445e+08

Sheet 3. HH-Total
B1: 2019-20 | G1: COLA | H1: 0.0271 | J1: ='2. Weighting'!B9 -> 0.0326
B2: Base Allocation (70%) | C2: Base (Noncredit and CDCP) | D2: Supplemental Allocation (20%) | E2: Student Success Allocation (10%) | F2: 2019-20 TCR Calculated | G2: 2017-18 R1-February Total Computational Revenue (TCR) | H2: 2017-18 TCR plus 17-18 COLA | I2: 2019-20 Minimum (2017-18 TCR Plus 17-18 COLA plus 18-19 COLA) | J2: Is 2019-20 TCR minimum larger than 2019-20 TCR Calculated? | K2: Hold Harmless amount | L2: If Basic Aid, then By Formula | M2: Hold Harmless Amount for Non Basic Aid districts | N2: 2019-20 Student Centered Funding Formula (SCFF) | O2: Annual % increase (change from 2018-19 TCR)
A3: District
A6: Allan Hancock | B6: ='5. Base Allocation'!G6 -> 43277346 | C6: =SUM('5. Base Allocation'!D6:E6) -> 2524254.7 | D6: ='6. Supplemental Allocation'!E6 -> 11705654 | E6: ='7. Success Allocation'!AF6 -> 6022630 | F6: =SUM(B6:E6) -> 63529885 | G6: 58423221 | H6: =(G6*H$1)+G6 -> 60006490 | I6: =(H6*J$1)+H6 -> 61962702 | J6: =IF(I6>F6,"Y"," " ) | K6: =IF((I6-F6)>1,(I6-F6),0) -> 0 | M6: =IF(L6="x",0,K6) -> 0 | N6: =F6+M6 -> 63529885 | O6: =(N6-H6)/H6 -> 0.058716888
A7: Antelope | B7: ='5. Base Allocation'!G7 -> 52485431 | C7: =SUM('5. Base Allocation'!D7:E7) -> 320851.32 | D7: ='6. Supplemental Allocation'!E7 -> 22000753 | E7: ='7. Success Allocation'!AF7 -> 6858936.3 | F7: =SUM(B7:E7) -> 81665972 | G7: 62613062 | H7: =(G7*H$1)+G7 -> 64309876 | I7: =(H7*J$1)+H7 -> 66406378 | J7: =IF(I7>F7,"Y"," " ) | K7: =IF((I7-F7)>1,(I7-F7),0) -> 0 | M7: =IF(L7="x",0,K7) -> 0 | N7: =F7+M7 -> 81665972 | O7: =(N7-H7)/H7 -> 0.26988229
A8: Barstow | B8: ='5. Base Allocation'!G8 -> 15616275 | C8: =SUM('5. Base Allocation'!D8:E8) -> 114667.61 | D8: ='6. Supplemental Allocation'!E8 -> 5084804.5 | E8: ='7. Success Allocation'!AF8 -> 1840942.2 | F8: =SUM(B8:E8) -> 22656689 | G8: 18681460 | H8: =(G8*H$1)+G8 -> 19187728 | I8: =(H8*J$1)+H8 -> 19813247 | J8: =IF(I8>F8,"Y"," " ) | K8: =IF((I8-F8)>1,(I8-F8),0) -> 0 | M8: =IF(L8="x",0,K8) -> 0 | N8: =F8+M8 -> 22656689 | O8: =(N8-H8)/H8 -> 0.18079064
A9: Butte | B9: ='5. Base Allocation'!G9 -> 45027897 | C9: =SUM('5. Base Allocation'!D9:E9) -> 4134774.7 | D9: ='6. Supplemental Allocation'!E9 -> 12607436 | E9: ='7. Success Allocation'!AF9 -> 7091455.4 | F9: =SUM(B9:E9) -> 68861562 | G9: 58869732 | H9: =(G9*H$1)+G9 -> 60465102 | I9: =(H9*J$1)+H9 -> 62436264 | J9: =IF(I9>F9,"Y"," " ) | K9: =IF((I9-F9)>1,(I9-F9),0) -> 0 | M9: =IF(L9="x",0,K9) -> 0 | N9: =F9+M9 -> 68861562 | O9: =(N9-H9)/H9 -> 0.13886457
A10: Cabrillo | B10: ='5. Base Allocation'!G10 -> 46030053 | C10: =SUM('5. Base Allocation'!D10:E10) -> 2848229.4 | D10: ='6. Supplemental Allocation'!E10 -> 9263935.9 | E10: ='7. Success Allocation'!AF10 -> 5098113.9 | F10: =SUM(B10:E10) -> 63240332 | G10: 61066687 | H10: =(G10*H$1)+G10 -> 62721594 | I10: =(H10*J$1)+H10 -> 64766318 | J10: =IF(I10>F10,"Y"," " ) -> Y | K10: =IF((I10-F10)>1,(I10-F10),0) -> 1525986 | M10: =IF(L10="x",0,K10) -> 1525986 | N10: =F10+M10 -> 64766318 | O10: =(N10-H10)/H10 -> 0.0326
A11: Cerritos | B11: ='5. Base Allocation'!G11 -> 71428552 | C11: =SUM('5. Base Allocation'!D11:E11) -> 2431479.5 | D11: ='6. Supplemental Allocation'!E11 -> 28669270 | E11: ='7. Success Allocation'!AF11 -> 11023663 | F11: =SUM(B11:E11) -> 1.1355296e+08 | G11: 93447643 | H11: =(G11*H$1)+G11 -> 95980074 | I11: =(H11*J$1)+H11 -> 99109025 | J11: =IF(I11>F11,"Y"," " ) | K11: =IF((I11-F11)>1,(I11-F11),0) -> 0 | M11: =IF(L11="x",0,K11) -> 0 | N11: =F11+M11 -> 1.1355296e+08 | O11: =(N11-H11)/H11 -> 0.18308894
A12: Chabot-Las Positas | B12: ='5. Base Allocation'!G12 -> 75647977 | C12: =SUM('5. Base Allocation'!D12:E12) -> 630265.78 | D12: ='6. Supplemental Allocation'!E12 -> 16014167 | E12: ='7. Success Allocation'!AF12 -> 9380162.2 | F12: =SUM(B12:E12) -> 1.0167257e+08 | G12: 107679794 | H12: =(G12*H$1)+G12 -> 1.1059792e+08 | I12: =(H12*J$1)+H12 -> 1.1420341e+08 | J12: =IF(I12>F12,"Y"," " ) -> Y | K12: =IF((I12-F12)>1,(I12-F12),0) -> 12530836 | M12: =IF(L12="x",0,K12) -> 12530836 | N12: =F12+M12 -> 1.1420341e+08 | O12: =(N12-H12)/H12 -> 0.0326
A13: Chaffey | B13: ='5. Base Allocation'!G13 -> 75223813 | C13: =SUM('5. Base Allocation'!D13:E13) -> 1197061.7 | D13: ='6. Supplemental Allocation'!E13 -> 27023299 | E13: ='7. Success Allocation'!AF13 -> 10113984 | F13: =SUM(B13:E13) -> 1.1355816e+08 | G13: 93669819 | H13: =(G13*H$1)+G13 -> 96208271 | I13: =(H13*J$1)+H13 -> 99344661 | J13: =IF(I13>F13,"Y"," " ) | K13: =IF((I13-F13)>1,(I13-F13),0) -> 0 | M13: =IF(L13="x",0,K13) -> 0 | N13: =F13+M13 -> 1.1355816e+08 | O13: =(N13-H13)/H13 -> 0.18033675
A14: Citrus | B14: ='5. Base Allocation'!G14 -> 52196342 | C14: =SUM('5. Base Allocation'!D14:E14) -> 1619531.1 | D14: ='6. Supplemental Allocation'!E14 -> 16367292 | E14: ='7. Success Allocation'!AF14 -> 7913455.7 | F14: =SUM(B14:E14) -> 78096621 | G14: 68139191 | H14: =(G14*H$1)+G14 -> 69985763 | I14: =(H14*J$1)+H14 -> 72267299 | J14: =IF(I14>F14,"Y"," " ) | K14: =IF((I14-F14)>1,(I14-F14),0) -> 0 | M14: =IF(L14="x",0,K14) -> 0 | N14: =F14+M14 -> 78096621 | O14: =(N14-H14)/H14 -> 0.11589297
A15: Coast | B15: ='5. Base Allocation'!G15 -> 1.4046044e+08 | C15: =SUM('5. Base Allocation'!D15:E15) -> 3102393.4 | D15: ='6. Supplemental Allocation'!E15 -> 43674647 | E15: ='7. Success Allocation'!AF15 -> 22704777 | F15: =SUM(B15:E15) -> 2.0994226e+08 | G15: 184284255 | H15: =(G15*H$1)+G15 -> 1.8927836e+08 | I15: =(H15*J$1)+H15 -> 1.9544883e+08 | J15: =IF(I15>F15,"Y"," " ) | K15: =IF((I15-F15)>1,(I15-F15),0) -> 0 | M15: =IF(L15="x",0,K15) -> 0 | N15: =F15+M15 -> 2.0994226e+08 | O15: =(N15-H15)/H15 -> 0.10917203
A16: Compton | B16: ='5. Base Allocation'!G16 -> 29447376 | C16: =SUM('5. Base Allocation'!D16:E16) -> 59555.869 | D16: ='6. Supplemental Allocation'!E16 -> 6702564.1 | E16: ='7. Success Allocation'!AF16 -> 2438232.5 | F16: =SUM(B16:E16) -> 38647729 | G16: 35475170 | H16: =(G16*H$1)+G16 -> 36436547 | I16: =(H16*J$1)+H16 -> 37624379 | J16: =IF(I16>F16,"Y"," " ) | K16: =IF((I16-F16)>1,(I16-F16),0) -> 0 | M16: =IF(L16="x",0,K16) -> 0 | N16: =F16+M16 -> 38647729 | O16: =(N16-H16)/H16 -> 0.060685821
A17: Contra Costa | B17: ='5. Base Allocation'!G17 -> 1.2498775e+08 | C17: =SUM('5. Base Allocation'!D17:E17) -> 524948.89 | D17: ='6. Supplemental Allocation'!E17 -> 27244124 | E17: ='7. Success Allocation'!AF17 -> 16118404 | F17: =SUM(B17:E17) -> 1.6887522e+08 | G17: 170246475 | H17: =(G17*H$1)+G17 -> 1.7486015e+08 | I17: =(H17*J$1)+H17 -> 1.805606e+08 | J17: =IF(I17>F17,"Y"," " ) -> Y | K17: =IF((I17-F17)>1,(I17-F17),0) -> 11685374 | M17: =IF(L17="x",0,K17) -> 11685374 | N17: =F17+M17 -> 1.805606e+08 | O17: =(N17-H17)/H17 -> 0.0326
... A33: Los Rios | B33: ='5. Base Allocation'!G33 -> 2.3516904e+08 | C33: =SUM('5. Base Allocation'!D33:E33) -> 943768.78 | D33: ='6. Supplemental Allocation'!E33 -> 69337005 | E33: ='7. Success Allocation'!AF33 -> 31054190 | F33: =SUM(B33:E33) -> 3.3650401e+08 | G33: 303959995 | H33: =(G33*H$1)+G33 -> 3.1219731e+08 | I33: =(H33*J$1)+H33 -> 3.2237494e+08 | J33: =IF(I33>F33,"Y"," " ) | K33: =IF((I33-F33)>1,(I33-F33),0) -> 0 | M33: =IF(L33="x",0,K33) -> 0 | N33: =F33+M33 -> 3.3650401e+08 | O33: =(N33-H33)/H33 -> 0.07785684
A34: Marin | B34: ='5. Base Allocation'!G34 -> 4855471.5 | C34: =SUM('5. Base Allocation'!D34:E34) -> 979615.09 | D34: ='6. Supplemental Allocation'!E34 -> 3067225.7 | E34: ='7. Success Allocation'!AF34 -> 1590837.4 | F34: =SUM(B34:E34) -> 10493150 | G34: 25606935 | H34: =(G34*H$1)+G34 -> 26300883 | I34: =(H34*J$1)+H34 -> 27158292 | J34: =IF(I34>F34,"Y"," " ) -> Y | K34: =IF((I34-F34)>1,(I34-F34),0) -> 16665142 | L34: x | M34: =IF(L34="x",0,K34) -> 0 | N34: =F34+M34 -> 10493150 | O34: =(N34-H34)/H34 -> -0.60103432
A35: Mendocino | B35: ='5. Base Allocation'!G35 -> 17938321 | C35: =SUM('5. Base Allocation'!D35:E35) -> 452369.47 | D35: ='6. Supplemental Allocation'!E35 -> 3983599.4 | E35: ='7. Success Allocation'!AF35 -> 1878362.6 | F35: =SUM(B35:E35) -> 24252652 | G35: 22434165 | H35: =(G35*H$1)+G35 -> 23042131 | I35: =(H35*J$1)+H35 -> 23793304 | J35: =IF(I35>F35,"Y"," " ) | K35: =IF((I35-F35)>1,(I35-F35),0) -> 0 | M35: =IF(L35="x",0,K35) -> 0 | N35: =F35+M35 -> 24252652 | O35: =(N35-H35)/H35 -> 0.052535132
A36: Merced | B36: ='5. Base Allocation'!G36 -> 42343131 | C36: =SUM('5. Base Allocation'!D36:E36) -> 5485849.8 | D36: ='6. Supplemental Allocation'!E36 -> 13899309 | E36: ='7. Success Allocation'!AF36 -> 6195176.4 | F36: =SUM(B36:E36) -> 67923466 | G36: 56496411 | H36: =(G36*H$1)+G36 -> 58027464 | I36: =(H36*J$1)+H36 -> 59919159 | J36: =IF(I36>F36,"Y"," " ) | K36: =IF((I36-F36)>1,(I36-F36),0) -> 0 | M36: =IF(L36="x",0,K36) -> 0 | N36: =F36+M36 -> 67923466 | O36: =(N36-H36)/H36 -> 0.17053998
A37: MiraCosta | B37: ='5. Base Allocation'!G37 -> 7327199.8 | C37: =SUM('5. Base Allocation'!D37:E37) -> 2545866.8 | D37: ='6. Supplemental Allocation'!E37 -> 13784519 | E37: ='7. Success Allocation'!AF37 -> 7402126.3 | F37: =SUM(B37:E37) -> 31059712 | G37: 63540067 | H37: =(G37*H$1)+G37 -> 65262003 | I37: =(H37*J$1)+H37 -> 67389544 | J37: =IF(I37>F37,"Y"," " ) -> Y | K37: =IF((I37-F37)>1,(I37-F37),0) -> 36329833 | L37: x | M37: =IF(L37="x",0,K37) -> 0 | N37: =F37+M37 -> 31059712 | O37: =(N37-H37)/H37 -> -0.52407664
A38: Monterey | B38: ='5. Base Allocation'!G38 -> 29147368 | C38: =SUM('5. Base Allocation'!D38:E38) -> 1025803.7 | D38: ='6. Supplemental Allocation'!E38 -> 7356283 | E38: ='7. Success Allocation'!AF38 -> 3976343.9 | F38: =SUM(B38:E38) -> 41505799 | G38: 38888873 | H38: =(G38*H$1)+G38 -> 39942761 | I38: =(H38*J$1)+H38 -> 41244895 | J38: =IF(I38>F38,"Y"," " ) | K38: =IF((I38-F38)>1,(I38-F38),0) -> 0 | M38: =IF(L38="x",0,K38) -> 0 | N38: =F38+M38 -> 41505799 | O38: =(N38-H38)/H38 -> 0.039131935
A39: Mt. San Antonio | B39: ='5. Base Allocation'!G39 -> 1.0999044e+08 | C39: =SUM('5. Base Allocation'!D39:E39) -> 43612915 | D39: ='6. Supplemental Allocation'!E39 -> 37544087 | E39: ='7. Success Allocation'!AF39 -> 13977536 | F39: =SUM(B39:E39) -> 2.0512498e+08 | G39: 176424297 | H39: =(G39*H$1)+G39 -> 1.812054e+08 | I39: =(H39*J$1)+H39 -> 1.8711269e+08 | J39: =IF(I39>F39,"Y"," " ) | K39: =IF((I39-F39)>1,(I39-F39),0) -> 0 | M39: =IF(L39="x",0,K39) -> 0 | N39: =F39+M39 -> 2.0512498e+08 | O39: =(N39-H39)/H39 -> 0.13200261
A40: Mt. San Jacinto | B40: ='5. Base Allocation'!G40 -> 53093514 | C40: =SUM('5. Base Allocation'!D40:E40) -> 2255378.6 | D40: ='6. Supplemental Allocation'!E40 -> 21251700 | E40: ='7. Success Allocation'!AF40 -> 7416744.6 | F40: =SUM(B40:E40) -> 84017337 | G40: 71517436 | H40: =(G40*H$1)+G40 -> 73455559 | I40: =(H40*J$1)+H40 -> 75850210 | J40: =IF(I40>F40,"Y"," " ) | K40: =IF((I40-F40)>1,(I40-F40),0) -> 0 | M40: =IF(L40="x",0,K40) -> 0 | N40: =F40+M40 -> 84017337 | O40: =(N40-H40)/H40 -> 0.14378461
A41: Napa | B41: ='5. Base Allocation'!G41 -> 23825034 | C41: =SUM('5. Base Allocation'!D41:E41) -> 1398680.8 | D41: ='6. Supplemental Allocation'!E41 -> 5408745.5 | E41: ='7. Success Allocation'!AF41 -> 3241928.6 | F41: =SUM(B41:E41) -> 33874389 | G41: 31620290 | H41: =(G41*H$1)+G41 -> 32477200 | I41: =(H41*J$1)+H41 -> 33535957 | J41: =IF(I41>F41,"Y"," " ) | K41: =IF((I41-F41)>1,(I41-F41),0) -> 0 | M41: =IF(L41="x",0,K41) -> 0 | N41: =F41+M41 -> 33874389 | O41: =(N41-H41)/H41 -> 0.04302062
A42: North Orange | B42: ='5. Base Allocation'!G42 -> 1.2567415e+08 | C42: =SUM('5. Base Allocation'!D42:E42) -> 17100139 | D42: ='6. Supplemental Allocation'!E42 -> 36481794 | E42: ='7. Success Allocation'!AF42 -> 17154275 | F42: =SUM(B42:E42) -> 1.9641035e+08 | G42: 202056270 | H42: =(G42*H$1)+G42 -> 2.0753199e+08 | I42: =(H42*J$1)+H42 -> 2.1429754e+08 | J42: =IF(I42>F42,"Y"," " ) -> Y | K42: =IF((I42-F42)>1,(I42-F42),0) -> 17887185 | M42: =IF(L42="x",0,K42) -> 17887185 | N42: =F42+M42 -> 2.1429754e+08 | O42: =(N42-H42)/H42 -> 0.0326
A43: Ohlone | B43: ='5. Base Allocation'!G43 -> 34980592 | C43: =SUM('5. Base Allocation'!D43:E43) -> 14076.562 | D43: ='6. Supplemental Allocation'!E43 -> 4920401.9 | E43: ='7. Success Allocation'!AF43 -> 4169099.8 | F43: =SUM(B43:E43) -> 44084170 | G43: 48764473 | H43: =(G43*H$1)+G43 -> 50085990 | I43: =(H43*J$1)+H43 -> 51718793 | J43: =IF(I43>F43,"Y"," " ) -> Y | K43: =IF((I43-F43)>1,(I43-F43),0) -> 7634623 | M43: =IF(L43="x",0,K43) -> 7634623 | N43: =F43+M43 -> 51718793 | O43: =(N43-H43)/H43 -> 0.0326
A44: Palo Verde | B44: ='5. Base Allocation'!G44 -> 14642160 | C44: =SUM('5. Base Allocation'!D44:E44) -> 127482.56 | D44: ='6. Supplemental Allocation'!E44 -> 3551678 | E44: ='7. Success Allocation'!AF44 -> 1023471 | F44: =SUM(B44:E44) -> 19344792 | G44: 16636774 | H44: =(G44*H$1)+G44 -> 17087631 | I44: =(H44*J$1)+H44 -> 17644687 | J44: =IF(I44>F44,"Y"," " ) | K44: =IF((I44-F44)>1,(I44-F44),0) -> 0 | M44: =IF(L44="x",0,K44) -> 0 | N44: =F44+M44 -> 19344792 | O44: =(N44-H44)/H44 -> 0.13209329
A45: Palomar | B45: ='5. Base Allocation'!G45 -> 79606427 | C45: =SUM('5. Base Allocation'!D45:E45) -> 3148760.8 | D45: ='6. Supplemental Allocation'!E45 -> 20702071 | E45: ='7. Success Allocation'!AF45 -> 9955899.8 | F45: =SUM(B45:E45) -> 1.1341316e+08 | G45: 108548444 | H45: =(G45*H$1)+G45 -> 1.1149011e+08 | I45: =(H45*J$1)+H45 -> 1.1512468e+08 | J45: =IF(I45>F45,"Y"," " ) -> Y | K45: =IF((I45-F45)>1,(I45-F45),0) -> 1711526.4 | M45: =IF(L45="x",0,K45) -> 1711526.4 | N45: =F45+M45 -> 1.1512468e+08 | O45: =(N45-H45)/H45 -> 0.0326
A46: Pasadena | B46: ='5. Base Allocation'!G46 -> 1.0276055e+08 | C46: =SUM('5. Base Allocation'!D46:E46) -> 5411051.6 | D46: ='6. Supplemental Allocation'!E46 -> 29492255 | E46: ='7. Success Allocation'!AF46 -> 14002805 | F46: =SUM(B46:E46) -> 1.5166667e+08 | G46: 134464486 | H46: =(G46*H$1)+G46 -> 1.3810847e+08 | I46: =(H46*J$1)+H46 -> 1.4261081e+08 | J46: =IF(I46>F46,"Y"," " ) | K46: =IF((I46-F46)>1,(I46-F46),0) -> 0 | M46: =IF(L46="x",0,K46) -> 0 | N46: =F46+M46 -> 1.5166667e+08 | O46: =(N46-H46)/H46 -> 0.098170602
A47: Peralta | B47: ='5. Base Allocation'!G47 -> 90491628 | C47: =SUM('5. Base Allocation'!D47:E47) -> 367340.15 | D47: ='6. Supplemental Allocation'!E47 -> 22486179 | E47: ='7. Success Allocation'!AF47 -> 9667500 | F47: =SUM(B47:E47) -> 1.2301265e+08 | G47: 114674531 | H47: =(G47*H$1)+G47 -> 1.1778221e+08 | I47: =(H47*J$1)+H47 -> 1.2162191e+08 | J47: =IF(I47>F47,"Y"," " ) | K47: =IF((I47-F47)>1,(I47-F47),0) -> 0 | M47: =IF(L47="x",0,K47) -> 0 | N47: =F47+M47 -> 1.2301265e+08 | O47: =(N47-H47)/H47 -> 0.044407693
A48: Rancho Santiago | B48: ='5. Base Allocation'!G48 -> 1.0831799e+08 | C48: =SUM('5. Base Allocation'!D48:E48) -> 31709982 | D48: ='6. Supplemental Allocation'!E48 -> 27167273 | E48: ='7. Success Allocation'!AF48 -> 15814605 | F48: =SUM(B48:E48) -> 1.8300985e+08 | G48: 164850888 | H48: =(G48*H$1)+G48 -> 1.6931835e+08 | I48: =(H48*J$1)+H48 -> 1.7483813e+08 | J48: =IF(I48>F48,"Y"," " ) | K48: =IF((I48-F48)>1,(I48-F48),0) -> 0 | M48: =IF(L48="x",0,K48) -> 0 | N48: =F48+M48 -> 1.8300985e+08 | O48: =(N48-H48)/H48 -> 0.080862465
A49: Redwoods | B49: ='5. Base Allocation'!G49 -> 21126249 | C49: =SUM('5. Base Allocation'!D49:E49) -> 663180.43 | D49: ='6. Supplemental Allocation'!E49 -> 5434038.2 | E49: ='7. Success Allocation'!AF49 -> 2720135.2 | F49: =SUM(B49:E49) -> 29943603 | G49: 26897607 | H49: =(G49*H$1)+G49 -> 27626532 | I49: =(H49*J$1)+H49 -> 28527157 | J49: =IF(I49>F49,"Y"," " ) | K49: =IF((I49-F49)>1,(I49-F49),0) -> 0 | M49: =IF(L49="x",0,K49) -> 0 | N49: =F49+M49 -> 29943603 | O49: =(N49-H49)/H49 -> 0.083871221
... A55: San Joaquin Delta | B55: ='5. Base Allocation'!G55 -> 70145492 | C55: =SUM('5. Base Allocation'!D55:E55) -> 570687.35 | D55: ='6. Supplemental Allocation'!E55 -> 21848024 | E55: ='7. Success Allocation'!AF55 -> 10507492 | F55: =SUM(B55:E55) -> 1.030717e+08 | G55: 90280054 | H55: =(G55*H$1)+G55 -> 92726643 | I55: =(H55*J$1)+H55 -> 95749532 | J55: =IF(I55>F55,"Y"," " ) | K55: =IF((I55-F55)>1,(I55-F55),0) -> 0 | M55: =IF(L55="x",0,K55) -> 0 | N55: =F55+M55 -> 1.030717e+08 | O55: =(N55-H55)/H55 -> 0.11156504
A56: San Jose | B56: ='5. Base Allocation'!G56 -> 9611863.4 | C56: =SUM('5. Base Allocation'!D56:E56) -> 849652.43 | D56: ='6. Supplemental Allocation'!E56 -> 16676641 | E56: ='7. Success Allocation'!AF56 -> 6830792.9 | F56: =SUM(B56:E56) -> 33968950 | G56: 70622433 | H56: =(G56*H$1)+G56 -> 72536301 | I56: =(H56*J$1)+H56 -> 74900984 | J56: =IF(I56>F56,"Y"," " ) -> Y | K56: =IF((I56-F56)>1,(I56-F56),0) -> 40932035 | L56: x | M56: =IF(L56="x",0,K56) -> 0 | N56: =F56+M56 -> 33968950 | O56: =(N56-H56)/H56 -> -0.53169724
A57: San Luis Obispo | B57: ='5. Base Allocation'!G57 -> 36476144 | C57: =SUM('5. Base Allocation'!D57:E57) -> 2824390.6 | D57: ='6. Supplemental Allocation'!E57 -> 8367018 | E57: ='7. Success Allocation'!AF57 -> 5057851 | F57: =SUM(B57:E57) -> 52725403 | G57: 49069768 | H57: =(G57*H$1)+G57 -> 50399559 | I57: =(H57*J$1)+H57 -> 52042584 | J57: =IF(I57>F57,"Y"," " ) | K57: =IF((I57-F57)>1,(I57-F57),0) -> 0 | M57: =IF(L57="x",0,K57) -> 0 | N57: =F57+M57 -> 52725403 | O57: =(N57-H57)/H57 -> 0.046148112
A58: San Mateo | B58: ='5. Base Allocation'!G58 -> 76566804 | C58: =SUM('5. Base Allocation'!D58:E58) -> 121863.94 | D58: ='6. Supplemental Allocation'!E58 -> 14429482 | E58: ='7. Success Allocation'!AF58 -> 9849448.3 | F58: =SUM(B58:E58) -> 1.009676e+08 | G58: 98289606 | H58: =(G58*H$1)+G58 -> 1.0095325e+08 | I58: =(H58*J$1)+H58 -> 1.0424433e+08 | J58: =IF(I58>F58,"Y"," " ) -> Y | K58: =IF((I58-F58)>1,(I58-F58),0) -> 3276731.9 | L58: x | M58: =IF(L58="x",0,K58) -> 0 | N58: =F58+M58 -> 1.009676e+08 | O58: =(N58-H58)/H58 -> 0.00014208762
A59: Santa Barbara | B59: ='5. Base Allocation'!G59 -> 53636912 | C59: =SUM('5. Base Allocation'!D59:E59) -> 5496355.4 | D59: ='6. Supplemental Allocation'!E59 -> 13069514 | E59: ='7. Success Allocation'!AF59 -> 8228093.6 | F59: =SUM(B59:E59) -> 80430874 | G59: 72610515 | H59: =(G59*H$1)+G59 -> 74578260 | I59: =(H59*J$1)+H59 -> 77009511 | J59: =IF(I59>F59,"Y"," " ) | K59: =IF((I59-F59)>1,(I59-F59),0) -> 0 | M59: =IF(L59="x",0,K59) -> 0 | N59: =F59+M59 -> 80430874 | O59: =(N59-H59)/H59 -> 0.078476145
A60: Santa Clarita | B60: ='5. Base Allocation'!G60 -> 73130945 | C60: =SUM('5. Base Allocation'!D60:E60) -> 1845416 | D60: ='6. Supplemental Allocation'!E60 -> 14247570 | E60: ='7. Success Allocation'!AF60 -> 10772809 | F60: =SUM(B60:E60) -> 99996739 | G60: 94448588 | H60: =(G60*H$1)+G60 -> 97008145 | I60: =(H60*J$1)+H60 -> 1.0017061e+08 | J60: =IF(I60>F60,"Y"," " ) -> Y | K60: =IF((I60-F60)>1,(I60-F60),0) -> 173870.94 | M60: =IF(L60="x",0,K60) -> 173870.94 | N60: =F60+M60 -> 1.0017061e+08 | O60: =(N60-H60)/H60 -> 0.0326
A61: Santa Monica | B61: ='5. Base Allocation'!G61 -> 9592377.4 | C61: =SUM('5. Base Allocation'!D61:E61) -> 2693049.8 | D61: ='6. Supplemental Allocation'!E61 -> 27413390 | E61: ='7. Success Allocation'!AF61 -> 12325351 | F61: =SUM(B61:E61) -> 52024168 | G61: 129918589 | H61: =(G61*H$1)+G61 -> 1.3343938e+08 | I61: =(H61*J$1)+H61 -> 1.3778951e+08 | J61: =IF(I61>F61,"Y"," " ) -> Y | K61: =IF((I61-F61)>1,(I61-F61),0) -> 85765338 | M61: =IF(L61="x",0,K61) -> 85765338 | N61: =F61+M61 -> 1.3778951e+08 | O61: =(N61-H61)/H61 -> 0.0326
A62: Sequoias | B62: ='5. Base Allocation'!G62 -> 49310200 | C62: =SUM('5. Base Allocation'!D62:E62) -> 1356776.3 | D62: ='6. Supplemental Allocation'!E62 -> 16687342 | E62: ='7. Success Allocation'!AF62 -> 6693105.7 | F62: =SUM(B62:E62) -> 74047424 | G62: 61392655 | H62: =(G62*H$1)+G62 -> 63056396 | I62: =(H62*J$1)+H62 -> 65112034 | J62: =IF(I62>F62,"Y"," " ) | K62: =IF((I62-F62)>1,(I62-F62),0) -> 0 | M62: =IF(L62="x",0,K62) -> 0 | N62: =F62+M62 -> 74047424 | O62: =(N62-H62)/H62 -> 0.17430472
...

Sheet 4. Compare
B2: 2018-19 (2017-18 plus COLA) | C2: 2019-20 Student Centered Funding Formula (SCFF) | E2: Difference 2019-20 SCFF minus 2018-19 TCR P1 | F2: Annual % increase (change from 2018-19 TCR)
A3: District
A6: Allan Hancock | B6: ='3. HH-Total'!H6 -> 60006490 | C6: ='3. HH-Total'!N6 -> 63529885 | E6: =C6-B6 -> 3523394.4 | F6: =E6/B6 -> 0.058716888
A7: Antelope | B7: ='3. HH-Total'!H7 -> 64309876 | C7: ='3. HH-Total'!N7 -> 81665972 | E7: =C7-B7 -> 17356096 | F7: =E7/B7 -> 0.26988229
A8: Barstow | B8: ='3. HH-Total'!H8 -> 19187728 | C8: ='3. HH-Total'!N8 -> 22656689 | E8: =C8-B8 -> 3468961.6 | F8: =E8/B8 -> 0.18079064
A9: Butte | B9: ='3. HH-Total'!H9 -> 60465102 | C9: ='3. HH-Total'!N9 -> 68861562 | E9: =C9-B9 -> 8396460.6 | F9: =E9/B9 -> 0.13886457
A10: Cabrillo | B10: ='3. HH-Total'!H10 -> 62721594 | C10: ='3. HH-Total'!N10 -> 64766318 | E10: =C10-B10 -> 2044724 | F10: =E10/B10 -> 0.0326
A11: Cerritos | B11: ='3. HH-Total'!H11 -> 95980074 | C11: ='3. HH-Total'!N11 -> 1.1355296e+08 | E11: =C11-B11 -> 17572890 | F11: =E11/B11 -> 0.18308894
A12: Chabot-Las Positas | B12: ='3. HH-Total'!H12 -> 1.1059792e+08 | C12: ='3. HH-Total'!N12 -> 1.1420341e+08 | E12: =C12-B12 -> 3605492.1 | F12: =E12/B12 -> 0.0326
A13: Chaffey | B13: ='3. HH-Total'!H13 -> 96208271 | C13: ='3. HH-Total'!N13 -> 1.1355816e+08 | E13: =C13-B13 -> 17349887 | F13: =E13/B13 -> 0.18033675
A14: Citrus | B14: ='3. HH-Total'!H14 -> 69985763 | C14: ='3. HH-Total'!N14 -> 78096621 | E14: =C14-B14 -> 8110857.9 | F14: =E14/B14 -> 0.11589297
A15: Coast | B15: ='3. HH-Total'!H15 -> 1.8927836e+08 | C15: ='3. HH-Total'!N15 -> 2.0994226e+08 | E15: =C15-B15 -> 20663903 | F15: =E15/B15 -> 0.10917203
A16: Compton | B16: ='3. HH-Total'!H16 -> 36436547 | C16: ='3. HH-Total'!N16 -> 38647729 | E16: =C16-B16 -> 2211181.8 | F16: =E16/B16 -> 0.060685821
A17: Contra Costa | B17: ='3. HH-Total'!H17 -> 1.7486015e+08 | C17: ='3. HH-Total'!N17 -> 1.805606e+08 | E17: =C17-B17 -> 5700441 | F17: =E17/B17 -> 0.0326
... A77: Yuba | B77: ='3. HH-Total'!H77 -> 50924003 | C77: ='3. HH-Total'!N77 -> 57605214 | E77: =C77-B77 -> 6681211.2 | F77: =E77/B77 -> 0.13119965
A78: Statewide Total | B78: =SUM(B6:B77) -> 6.9503058e+09 | C78: ='3. HH-Total'!N78 -> 7.3370407e+09 | E78: =C78-B78 -> 3.8673488e+08 | F78: =E78/B78 -> 0.055642858

Sheet 5. Base Allocation
H2: RATES DOF
A3: District | B3: Basic Allocation DOF | C3: Base | F3: Special Admit Students and Students in Correctional Facilities Credit FTES | G3: Base Allocation Total (70%) | I3: Base FTES | L3: Special Admit Students and Students in Correctional Facilities Credit FTES
C4: Credit | D4: Noncredit | E4: CDCP | F4: Credit | I4: Credit | J4: Noncredit | K4: CDCP | L4: Credit
A6: Allan Hancock | B6: 6742470.1 | C6: ='5a. Base Counts'!B6*I6 -> 33873118 | D6: ='5a. Base Counts'!C6*J6 -> 1215345.8 | E6: ='5a. Base Counts'!D6*K6 -> 1308908.9 | F6: ='5a. Base Counts'!E6*L6 -> 2661757.6 | G6: =SUM(B6+C6+F6) -> 43277346 | I6: ='2. Weighting'!E$20 -> 4123.5 | J6: ='2. Weighting'!E$15 -> 3383.8562 | K6: ='2. Weighting'!E$16 -> 5638.1225 | L6: ='2. Weighting'!E$21 -> 5638.1225
A7: Antelope | B7: 6742470.1 | C7: ='5a. Base Counts'!B7*I7 -> 43594517 | D7: ='5a. Base Counts'!C7*J7 -> 28909.45 | E7: ='5a. Base Counts'!D7*K7 -> 291941.87 | F7: ='5a. Base Counts'!E7*L7 -> 2148444.2 | G7: =SUM(B7+C7+F7) -> 52485431 | I7: ='2. Weighting'!E$20 -> 4123.5 | J7: ='2. Weighting'!E$15 -> 3383.8562 | K7: ='2. Weighting'!E$16 -> 5638.1225 | L7: ='2. Weighting'!E$21 -> 5638.1225
A8: Barstow | B8: 5332192.5 | C8: ='5a. Base Counts'!B8*I8 -> 10284082 | D8: ='5a. Base Counts'!C8*J8 -> 114667.61 | E8: ='5a. Base Counts'!D8*K8 -> 0 | F8: ='5a. Base Counts'!E8*L8 -> 0 | G8: =SUM(B8+C8+F8) -> 15616275 | I8: ='2. Weighting'!E$20 -> 4123.5 | J8: ='2. Weighting'!E$15 -> 3383.8562 | K8: ='2. Weighting'!E$16 -> 5638.1225 | L8: ='2. Weighting'!E$21 -> 5638.1225
A9: Butte | B9: 6742470.1 | C9: ='5a. Base Counts'!B9*I9 -> 37212755 | D9: ='5a. Base Counts'!C9*J9 -> 3990514 | E9: ='5a. Base Counts'!D9*K9 -> 144260.76 | F9: ='5a. Base Counts'!E9*L9 -> 1072671.6 | G9: =SUM(B9+C9+F9) -> 45027897 | I9: ='2. Weighting'!E$20 -> 4123.5 | J9: ='2. Weighting'!E$15 -> 3383.8562 | K9: ='2. Weighting'!E$16 -> 5638.1225 | L9: ='2. Weighting'!E$21 -> 5638.1225
A10: Cabrillo | B10: 6742470.1 | C10: ='5a. Base Counts'!B10*I10 -> 38180462 | D10: ='5a. Base Counts'!C10*J10 -> 2356416 | E10: ='5a. Base Counts'!D10*K10 -> 491813.42 | F10: ='5a. Base Counts'!E10*L10 -> 1107120.5 | G10: =SUM(B10+C10+F10) -> 46030053 | I10: ='2. Weighting'!E$20 -> 4123.5 | J10: ='2. Weighting'!E$15 -> 3383.8562 | K10: ='2. Weighting'!E$16 -> 5638.1225 | L10: ='2. Weighting'!E$21 -> 5638.1225
A11: Cerritos | B11: 5393976.1 | C11: ='5a. Base Counts'!B11*I11 -> 65357305 | D11: ='5a. Base Counts'!C11*J11 -> 1079608 | E11: ='5a. Base Counts'!D11*K11 -> 1351871.4 | F11: ='5a. Base Counts'!E11*L11 -> 677270.07 | G11: =SUM(B11+C11+F11) -> 71428552 | I11: ='2. Weighting'!E$20 -> 4123.5 | J11: ='2. Weighting'!E$15 -> 3383.8562 | K11: ='2. Weighting'!E$16 -> 5638.1225 | L11: ='2. Weighting'!E$21 -> 5638.1225
A12: Chabot-Las Positas | B12: 8765209.6 | C12: ='5a. Base Counts'!B12*I12 -> 64366605 | D12: ='5a. Base Counts'!C12*J12 -> 630265.78 | E12: ='5a. Base Counts'!D12*K12 -> 0 | F12: ='5a. Base Counts'!E12*L12 -> 2516162.5 | G12: =SUM(B12+C12+F12) -> 75647977 | I12: ='2. Weighting'!E$20 -> 4123.5 | J12: ='2. Weighting'!E$15 -> 3383.8562 | K12: ='2. Weighting'!E$16 -> 5638.1225 | L12: ='2. Weighting'!E$21 -> 5638.1225
A13: Chaffey | B13: 8090964.1 | C13: ='5a. Base Counts'!B13*I13 -> 65131654 | D13: ='5a. Base Counts'!C13*J13 -> 1197061.7 | E13: ='5a. Base Counts'!D13*K13 -> 0 | F13: ='5a. Base Counts'!E13*L13 -> 2001195.2 | G13: =SUM(B13+C13+F13) -> 75223813 | I13: ='2. Weighting'!E$20 -> 4123.5 | J13: ='2. Weighting'!E$15 -> 3383.8562 | K13: ='2. Weighting'!E$16 -> 5638.1225 | L13: ='2. Weighting'!E$21 -> 5638.1225
A14: Citrus | B14: 5393976.1 | C14: ='5a. Base Counts'!B14*I14 -> 44713855 | D14: ='5a. Base Counts'!C14*J14 -> 1084435.7 | E14: ='5a. Base Counts'!D14*K14 -> 535095.41 | F14: ='5a. Base Counts'!E14*L14 -> 2088510.9 | G14: =SUM(B14+C14+F14) -> 52196342 | I14: ='2. Weighting'!E$20 -> 4123.5 | J14: ='2. Weighting'!E$15 -> 3383.8562 | K14: ='2. Weighting'!E$16 -> 5638.1225 | L14: ='2. Weighting'!E$21 -> 5638.1225
A15: Coast | B15: 12810690 | C15: ='5a. Base Counts'!B15*I15 -> 1.2651142e+08 | D15: ='5a. Base Counts'!C15*J15 -> 160327.11 | E15: ='5a. Base Counts'!D15*K15 -> 2942066.3 | F15: ='5a. Base Counts'!E15*L15 -> 1138336.9 | G15: =SUM(B15+C15+F15) -> 1.4046044e+08 | I15: ='2. Weighting'!E$20 -> 4123.5 | J15: ='2. Weighting'!E$15 -> 3383.8562 | K15: ='2. Weighting'!E$16 -> 5638.1225 | L15: ='2. Weighting'!E$21 -> 5638.1225
A16: Compton | B16: 4045480 | C16: ='5a. Base Counts'!B16*I16 -> 23964209 | D16: ='5a. Base Counts'!C16*J16 -> 59555.869 | E16: ='5a. Base Counts'!D16*K16 -> 0 | F16: ='5a. Base Counts'!E16*L16 -> 1437687.5 | G16: =SUM(B16+C16+F16) -> 29447376 | I16: ='2. Weighting'!E$20 -> 4123.5 | J16: ='2. Weighting'!E$15 -> 3383.8562 | K16: ='2. Weighting'!E$16 -> 5638.1225 | L16: ='2. Weighting'!E$21 -> 5638.1225
A17: Contra Costa | B17: 15507678 | C17: ='5a. Base Counts'!B17*I17 -> 1.0404195e+08 | D17: ='5a. Base Counts'!C17*J17 -> 524948.89 | E17: ='5a. Base Counts'!D17*K17 -> 0 | F17: ='5a. Base Counts'!E17*L17 -> 5438119.5 | G17: =SUM(B17+C17+F17) -> 1.2498775e+08 | I17: ='2. Weighting'!E$20 -> 4123.5 | J17: ='2. Weighting'!E$15 -> 3383.8562 | K17: ='2. Weighting'!E$16 -> 5638.1225 | L17: ='2. Weighting'!E$21 -> 5638.1225
... A21: Feather River | B21: 5332192.5 | C21: ='5a. Base Counts'!B21*I21 -> 5490875.1 | D21: ='5a. Base Counts'!C21*J21 -> 127289.39 | E21: ='5a. Base Counts'!D21*K21 -> 0 | F21: ='5a. Base Counts'!E21*L21 -> 1340295.9 | G21: =SUM(B21+C21+F21) -> 12163363 | I21: ='2. Weighting'!E$20 -> 4123.5 | J21: ='2. Weighting'!E$15 -> 3383.8562 | K21: ='2. Weighting'!E$16 -> 5638.1225 | L21: ='2. Weighting'!E$21 -> 5638.1225
A22: Foothill-De Anza3 | B22: 10787952 | C22: ='5a. Base Counts'!B22*I22 -> 90407220 | D22: ='5a. Base Counts'!C22*J22 -> 778275.65 | E22: ='5a. Base Counts'!D22*K22 -> 1782905.9 | F22: ='5a. Base Counts'!E22*L22 -> 4708358.5 | G22: =SUM(B22+C22+F22) -> 1.0590353e+08 | I22: ='2. Weighting'!E20+'2. Weighting'!I20 -> 4123.5 | J22: ='2. Weighting'!E$15 -> 3383.8562 | K22: ='2. Weighting'!E$16 -> 5638.1225 | L22: ='2. Weighting'!E$21 -> 5638.1225
A23: Gavilan | B23: 5332192.5 | C23: ='5a. Base Counts'!B23*I23 -> 18781730 | D23: ='5a. Base Counts'!C23*J23 -> 591781.18 | E23: ='5a. Base Counts'!D23*K23 -> 669940.51 | F23: ='5a. Base Counts'!E23*L23 -> 1357847.8 | G23: =SUM(B23+C23+F23) -> 25471770 | I23: ='2. Weighting'!E$20 -> 4123.5 | J23: ='2. Weighting'!E$15 -> 3383.8562 | K23: ='2. Weighting'!E$16 -> 5638.1225 | L23: ='2. Weighting'!E$21 -> 5638.1225
A24: Glendale | B24: 6742470.1 | C24: ='5a. Base Counts'!B24*I24 -> 43993118 | D24: ='5a. Base Counts'!C24*J24 -> 452375.14 | E24: ='5a. Base Counts'!D24*K24 -> 13488625 | F24: ='5a. Base Counts'!E24*L24 -> 1850488.2 | G24: =SUM(B24+C24+F24) -> 52586076 | I24: ='2. Weighting'!E$20 -> 4123.5 | J24: ='2. Weighting'!E$15 -> 3383.8562 | K24: ='2. Weighting'!E$16 -> 5638.1225 | L24: ='2. Weighting'!E$21 -> 5638.1225
A25: Grossmont-Cuyamaca | B25: 8765209.6 | C25: ='5a. Base Counts'!B25*I25 -> 70701554 | D25: ='5a. Base Counts'!C25*J25 -> 50994.713 | E25: ='5a. Base Counts'!D25*K25 -> 0 | F25: ='5a. Base Counts'!E25*L25 -> 1632029.7 | G25: =SUM(B25+C25+F25) -> 81098793 | I25: ='2. Weighting'!E$20 -> 4123.5 | J25: ='2. Weighting'!E$15 -> 3383.8562 | K25: ='2. Weighting'!E$16 -> 5638.1225 | L25: ='2. Weighting'!E$21 -> 5638.1225
A26: Hartnell | B26: 4382603.3 | C26: ='5a. Base Counts'!B26*I26 -> 29675905 | D26: ='5a. Base Counts'!C26*J26 -> 73158.971 | E26: ='5a. Base Counts'!D26*K26 -> 115017.7 | F26: ='5a. Base Counts'!E26*L26 -> 929031.18 | G26: =SUM(B26+C26+F26) -> 34987539 | I26: ='2. Weighting'!E$20 -> 4123.5 | J26: ='2. Weighting'!E$15 -> 3383.8562 | K26: ='2. Weighting'!E$16 -> 5638.1225 | L26: ='2. Weighting'!E$21 -> 5638.1225
A27: Imperial | B27: 4045480 | C27: ='5a. Base Counts'!B27*I27 -> 29769526 | D27: ='5a. Base Counts'!C27*J27 -> 109197.04 | E27: ='5a. Base Counts'!D27*K27 -> 59801.686 | F27: ='5a. Base Counts'!E27*L27 -> 1650389 | G27: =SUM(B27+C27+F27) -> 35465394 | I27: ='2. Weighting'!E$20 -> 4123.5 | J27: ='2. Weighting'!E$15 -> 3383.8562 | K27: ='2. Weighting'!E$16 -> 5638.1225 | L27: ='2. Weighting'!E$21 -> 5638.1225
A28: Kern | B28: 17024735 | C28: ='5a. Base Counts'!B28*I28 -> 90114800 | D28: ='5a. Base Counts'!C28*J28 -> 257759.61 | E28: ='5a. Base Counts'!D28*K28 -> 328627.37 | F28: ='5a. Base Counts'!E28*L28 -> 6597103.2 | G28: =SUM(B28+C28+F28) -> 1.1373664e+08 | I28: ='2. Weighting'!E$20 -> 4123.5 | J28: ='2. Weighting'!E$15 -> 3383.8562 | K28: ='2. Weighting'!E$16 -> 5638.1225 | L28: ='2. Weighting'!E$21 -> 5638.1225
A29: Lake Tahoe | B29: 5332192.5 | C29: ='5a. Base Counts'!B29*I29 -> 0 | D29: ='5a. Base Counts'!C29*J29 -> 189371.96 | E29: ='5a. Base Counts'!D29*K29 -> 11163.483 | F29: ='5a. Base Counts'!E29*L29 -> 749023.83 | G29: =SUM(B29+C29+F29) -> 6081216.4 | I29: ='2. Weighting'!E20*'2. Weighting'!I21 -> 0 | J29: ='2. Weighting'!E$15 -> 3383.8562 | K29: ='2. Weighting'!E$16 -> 5638.1225 | L29: ='2. Weighting'!E$21 -> 5638.1225
A30: Lassen | B30: 5332192.5 | C30: ='5a. Base Counts'!B30*I30 -> 0 | D30: ='5a. Base Counts'!C30*J30 -> 16366.585 | E30: ='5a. Base Counts'!D30*K30 -> 11332.626 | F30: ='5a. Base Counts'!E30*L30 -> 5072930.9 | G30: =SUM(B30+C30+F30) -> 10405123 | I30: ='2. Weighting'!E20*'2. Weighting'!I22 -> 0 | J30: ='2. Weighting'!E$15 -> 3383.8562 | K30: ='2. Weighting'!E$16 -> 5638.1225 | L30: ='2. Weighting'!E$21 -> 5638.1225
A31: Long Beach | B31: 8090964.1 | C31: ='5a. Base Counts'!B31*I31 -> 75537503 | D31: ='5a. Base Counts'!C31*J31 -> 107606.63 | E31: ='5a. Base Counts'!D31*K31 -> 2223825.9 | F31: ='5a. Base Counts'!E31*L31 -> 1136307.2 | G31: =SUM(B31+C31+F31) -> 84764774 | I31: ='2. Weighting'!E$20 -> 4123.5 | J31: ='2. Weighting'!E$15 -> 3383.8562 | K31: ='2. Weighting'!E$16 -> 5638.1225 | L31: ='2. Weighting'!E$21 -> 5638.1225
A32: Los Angeles | B32: 40454814 | C32: ='5a. Base Counts'!B32*I32 -> 3.486403e+08 | D32: ='5a. Base Counts'!C32*J32 -> 9533315.5 | E32: ='5a. Base Counts'!D32*K32 -> 26429846 | F32: ='5a. Base Counts'!E32*L32 -> 31674089 | G32: =SUM(B32+C32+F32) -> 4.207692e+08 | I32: ='2. Weighting'!E$20 -> 4123.5 | J32: ='2. Weighting'!E$15 -> 3383.8562 | K32: ='2. Weighting'!E$16 -> 5638.1225 | L32: ='2. Weighting'!E$21 -> 5638.1225
A33: Los Rios | B33: 26295631 | C33: ='5a. Base Counts'!B33*I33 -> 2.0450097e+08 | D33: ='5a. Base Counts'!C33*J33 -> 943768.78 | E33: ='5a. Base Counts'!D33*K33 -> 0 | F33: ='5a. Base Counts'!E33*L33 -> 4372439.2 | G33: =SUM(B33+C33+F33) -> 2.3516904e+08 | I33: ='2. Weighting'!E$20 -> 4123.5 | J33: ='2. Weighting'!E$15 -> 3383.8562 | K33: ='2. Weighting'!E$16 -> 5638.1225 | L33: ='2. Weighting'!E$21 -> 5638.1225
A34: Marin | B34: 4045480 | C34: ='5a. Base Counts'!B34*I34 -> 0 | D34: ='5a. Base Counts'!C34*J34 -> 979615.09 | E34: ='5a. Base Counts'!D34*K34 -> 0 | F34: ='5a. Base Counts'!E34*L34 -> 809991.47 | G34: =SUM(B34+C34+F34) -> 4855471.5 | I34: ='2. Weighting'!E20*'2. Weighting'!I23 -> 0 | J34: ='2. Weighting'!E$15 -> 3383.8562 | K34: ='2. Weighting'!E$16 -> 5638.1225 | L34: ='2. Weighting'!E$21 -> 5638.1225
A35: Mendocino | B35: 6343562.3 | C35: ='5a. Base Counts'!B35*I35 -> 10015088 | D35: ='5a. Base Counts'!C35*J35 -> 91792.74 | E35: ='5a. Base Counts'!D35*K35 -> 360576.73 | F35: ='5a. Base Counts'!E35*L35 -> 1579670.4 | G35: =SUM(B35+C35+F35) -> 17938321 | I35: ='2. Weighting'!E$20 -> 4123.5 | J35: ='2. Weighting'!E$15 -> 3383.8562 | K35: ='2. Weighting'!E$16 -> 5638.1225 | L35: ='2. Weighting'!E$21 -> 5638.1225
A36: Merced | B36: 5393974 | C36: ='5a. Base Counts'!B36*I36 -> 35380606 | D36: ='5a. Base Counts'!C36*J36 -> 1597913.3 | E36: ='5a. Base Counts'!D36*K36 -> 3887936.5 | F36: ='5a. Base Counts'!E36*L36 -> 1568551.4 | G36: =SUM(B36+C36+F36) -> 42343131 | I36: ='2. Weighting'!E$20 -> 4123.5 | J36: ='2. Weighting'!E$15 -> 3383.8562 | K36: ='2. Weighting'!E$16 -> 5638.1225 | L36: ='2. Weighting'!E$21 -> 5638.1225
A37: MiraCosta | B37: 6742470.1 | C37: ='5a. Base Counts'!B37*I37 -> 0 | D37: ='5a. Base Counts'!C37*J37 -> 2545866.8 | E37: ='5a. Base Counts'!D37*K37 -> 0 | F37: ='5a. Base Counts'!E37*L37 -> 584729.68 | G37: =SUM(B37+C37+F37) -> 7327199.8 | I37: ='2. Weighting'!E20*'2. Weighting'!I24 -> 0 | J37: ='2. Weighting'!E$15 -> 3383.8562 | K37: ='2. Weighting'!E$16 -> 5638.1225 | L37: ='2. Weighting'!E$21 -> 5638.1225
A38: Monterey | B38: 4382603.3 | C38: ='5a. Base Counts'!B38*I38 -> 23845394 | D38: ='5a. Base Counts'!C38*J38 -> 996241.11 | E38: ='5a. Base Counts'!D38*K38 -> 29562.556 | F38: ='5a. Base Counts'!E38*L38 -> 919371.04 | G38: =SUM(B38+C38+F38) -> 29147368 | I38: ='2. Weighting'!E$20 -> 4123.5 | J38: ='2. Weighting'!E$15 -> 3383.8562 | K38: ='2. Weighting'!E$16 -> 5638.1225 | L38: ='2. Weighting'!E$21 -> 5638.1225
A39: Mt. San Antonio | B39: 6742470.1 | C39: ='5a. Base Counts'!B39*I39 -> 1.0295976e+08 | D39: ='5a. Base Counts'!C39*J39 -> 5555344.4 | E39: ='5a. Base Counts'!D39*K39 -> 38057571 | F39: ='5a. Base Counts'!E39*L39 -> 288211.21 | G39: =SUM(B39+C39+F39) -> 1.0999044e+08 | I39: ='2. Weighting'!E$20 -> 4123.5 | J39: ='2. Weighting'!E$15 -> 3383.8562 | K39: ='2. Weighting'!E$16 -> 5638.1225 | L39: ='2. Weighting'!E$21 -> 5638.1225
A40: Mt. San Jacinto | B40: 6742470.1 | C40: ='5a. Base Counts'!B40*I40 -> 45362963 | D40: ='5a. Base Counts'!C40*J40 -> 769827.29 | E40: ='5a. Base Counts'!D40*K40 -> 1485551.3 | F40: ='5a. Base Counts'!E40*L40 -> 988080.96 | G40: =SUM(B40+C40+F40) -> 53093514 | I40: ='2. Weighting'!E$20 -> 4123.5 | J40: ='2. Weighting'!E$15 -> 3383.8562 | K40: ='2. Weighting'!E$16 -> 5638.1225 | L40: ='2. Weighting'!E$21 -> 5638.1225
A41: Napa | B41: 4719726.5 | C41: ='5a. Base Counts'!B41*I41 -> 18349442 | D41: ='5a. Base Counts'!C41*J41 -> 1377838.6 | E41: ='5a. Base Counts'!D41*K41 -> 20842.259 | F41: ='5a. Base Counts'!E41*L41 -> 755865.49 | G41: =SUM(B41+C41+F41) -> 23825034 | I41: ='2. Weighting'!E$20 -> 4123.5 | J41: ='2. Weighting'!E$15 -> 3383.8562 | K41: ='2. Weighting'!E$16 -> 5638.1225 | L41: ='2. Weighting'!E$21 -> 5638.1225
A42: North Orange | B42: 10787952 | C42: ='5a. Base Counts'!B42*I42 -> 1.1111713e+08 | D42: ='5a. Base Counts'!C42*J42 -> 16911769 | E42: ='5a. Base Counts'!D42*K42 -> 188369.67 | F42: ='5a. Base Counts'!E42*L42 -> 3769066.1 | G42: =SUM(B42+C42+F42) -> 1.2567415e+08 | I42: ='2. Weighting'!E$20 -> 4123.5 | J42: ='2. Weighting'!E$15 -> 3383.8562 | K42: ='2. Weighting'!E$16 -> 5638.1225 | L42: ='2. Weighting'!E$21 -> 5638.1225
A43: Ohlone | B43: 5393974 | C43: ='5a. Base Counts'!B43*I43 -> 29189826 | D43: ='5a. Base Counts'!C43*J43 -> 169.19281 | E43: ='5a. Base Counts'!D43*K43 -> 13907.369 | F43: ='5a. Base Counts'!E43*L43 -> 396792.27 | G43: =SUM(B43+C43+F43) -> 34980592 | I43: ='2. Weighting'!E$20 -> 4123.5 | J43: ='2. Weighting'!E$15 -> 3383.8562 | K43: ='2. Weighting'!E$16 -> 5638.1225 | L43: ='2. Weighting'!E$21 -> 5638.1225
A44: Palo Verde | B44: 5500755.2 | C44: ='5a. Base Counts'!B44*I44 -> 5546298.1 | D44: ='5a. Base Counts'!C44*J44 -> 93541.065 | E44: ='5a. Base Counts'!D44*K44 -> 33941.497 | F44: ='5a. Base Counts'!E44*L44 -> 3595107 | G44: =SUM(B44+C44+F44) -> 14642160 | I44: ='2. Weighting'!E$20 -> 4123.5 | J44: ='2. Weighting'!E$15 -> 3383.8562 | K44: ='2. Weighting'!E$16 -> 5638.1225 | L44: ='2. Weighting'!E$21 -> 5638.1225
A45: Palomar | B45: 6742470.1 | C45: ='5a. Base Counts'!B45*I45 -> 69926006 | D45: ='5a. Base Counts'!C45*J45 -> 922247.45 | E45: ='5a. Base Counts'!D45*K45 -> 2226513.4 | F45: ='5a. Base Counts'!E45*L45 -> 2937950.4 | G45: =SUM(B45+C45+F45) -> 79606427 | I45: ='2. Weighting'!E$20 -> 4123.5 | J45: ='2. Weighting'!E$15 -> 3383.8562 | K45: ='2. Weighting'!E$16 -> 5638.1225 | L45: ='2. Weighting'!E$21 -> 5638.1225
...

Sheet 5a. Base Counts
B2: 2019-20 Using Projections
B3: Credit FTES (Three year average 2017-18, 2018-19, projected 2019-20) | C3: Noncredit (Single year 2019-20) | D3: CDCP (Single year 2019-20) | E3: Special Admit Students and Students in Correctional Facilities Credit FTES (Single Year 2019-20)
A6: Allan Hancock | B6: =AVERAGE('5b. Base Hist'!Z11,'5b. Base Hist'!T11,'5b. Base Hist'!N11) -> 8214.6522 | C6: ='5b. Base Hist'!V11 -> 359.16 | D6: ='5b. Base Hist'!W11 -> 232.15333 | E6: ='5b. Base Hist'!X11+'5b. Base Hist'!Y11 -> 472.1
A7: Antelope | B7: =AVERAGE('5b. Base Hist'!Z12,'5b. Base Hist'!T12,'5b. Base Hist'!N12) -> 10572.212 | C7: ='5b. Base Hist'!V12 -> 8.5433447 | D7: ='5b. Base Hist'!W12 -> 51.779981 | E7: ='5b. Base Hist'!X12+'5b. Base Hist'!Y12 -> 381.05667
A8: Barstow | B8: =AVERAGE('5b. Base Hist'!Z13,'5b. Base Hist'!T13,'5b. Base Hist'!N13) -> 2494.0178 | C8: ='5b. Base Hist'!V13 -> 33.886667 | D8: ='5b. Base Hist'!W13 -> 0 | E8: ='5b. Base Hist'!X13+'5b. Base Hist'!Y13 -> 0
A9: Butte | B9: =AVERAGE('5b. Base Hist'!Z14,'5b. Base Hist'!T14,'5b. Base Hist'!N14) -> 9024.5556 | C9: ='5b. Base Hist'!V14 -> 1179.28 | D9: ='5b. Base Hist'!W14 -> 25.586667 | E9: ='5b. Base Hist'!X14+'5b. Base Hist'!Y14 -> 190.25333
A10: Cabrillo | B10: =AVERAGE('5b. Base Hist'!Z15,'5b. Base Hist'!T15,'5b. Base Hist'!N15) -> 9259.2367 | C10: ='5b. Base Hist'!V15 -> 696.37 | D10: ='5b. Base Hist'!W15 -> 87.23 | E10: ='5b. Base Hist'!X15+'5b. Base Hist'!Y15 -> 196.36333
A11: Cerritos | B11: =AVERAGE('5b. Base Hist'!Z16,'5b. Base Hist'!T16,'5b. Base Hist'!N16) -> 15849.959 | C11: ='5b. Base Hist'!V16 -> 319.04667 | D11: ='5b. Base Hist'!W16 -> 239.77333 | E11: ='5b. Base Hist'!X16+'5b. Base Hist'!Y16 -> 120.12333
A12: Chabot-Las Positas | B12: =AVERAGE('5b. Base Hist'!Z17,'5b. Base Hist'!T17,'5b. Base Hist'!N17) -> 15609.702 | C12: ='5b. Base Hist'!V17 -> 186.25667 | D12: ='5b. Base Hist'!W17 -> 0 | E12: ='5b. Base Hist'!X17+'5b. Base Hist'!Y17 -> 446.27667
A13: Chaffey | B13: =AVERAGE('5b. Base Hist'!Z18,'5b. Base Hist'!T18,'5b. Base Hist'!N18) -> 15795.236 | C13: ='5b. Base Hist'!V18 -> 353.75667 | D13: ='5b. Base Hist'!W18 -> 0 | E13: ='5b. Base Hist'!X18+'5b. Base Hist'!Y18 -> 354.94
A14: Citrus | B14: =AVERAGE('5b. Base Hist'!Z19,'5b. Base Hist'!T19,'5b. Base Hist'!N19) -> 10843.666 | C14: ='5b. Base Hist'!V19 -> 320.47333 | D14: ='5b. Base Hist'!W19 -> 94.906667 | E14: ='5b. Base Hist'!X19+'5b. Base Hist'!Y19 -> 370.42667
A15: Coast | B15: =AVERAGE('5b. Base Hist'!Z20,'5b. Base Hist'!T20,'5b. Base Hist'!N20) -> 30680.591 | C15: ='5b. Base Hist'!V20 -> 47.38 | D15: ='5b. Base Hist'!W20 -> 521.81667 | E15: ='5b. Base Hist'!X20+'5b. Base Hist'!Y20 -> 201.9
A16: Compton | B16: =AVERAGE('5b. Base Hist'!Z21,'5b. Base Hist'!T21,'5b. Base Hist'!N21) -> 5811.6185 | C16: ='5b. Base Hist'!V21 -> 17.6 | D16: ='5b. Base Hist'!W21 -> 0 | E16: ='5b. Base Hist'!X21+'5b. Base Hist'!Y21 -> 254.99402
A17: Contra Costa | B17: =AVERAGE('5b. Base Hist'!Z22,'5b. Base Hist'!T22,'5b. Base Hist'!N22) -> 25231.466 | C17: ='5b. Base Hist'!V22 -> 155.13333 | D17: ='5b. Base Hist'!W22 -> 0 | E17: ='5b. Base Hist'!X22+'5b. Base Hist'!Y22 -> 964.52667
... A77: Yuba | B77: =AVERAGE('5b. Base Hist'!Z82,'5b. Base Hist'!T82,'5b. Base Hist'!N82) -> 7231.0819 | C77: ='5b. Base Hist'!V82 -> 117.56667 | D77: ='5b. Base Hist'!W82 -> 2.2266667 | E77: ='5b. Base Hist'!X82+'5b. Base Hist'!Y82 -> 106.77986
A78: Statewide Total | B78: =SUM(B6:B77) -> 1003674 | C78: =SUM(C6:C77) -> 35123.935 | D78: =SUM(D6:D77) -> 39437.772 | E78: =SUM(E6:E77) -> 40889.824

Sheet 5b. Base Hist
B5: 2016-17 | I5: 2017-18 | O5: 2018-19 | U5: Projections use change between 1617 and1718 and change between 1718 and 1819 and weight the latter twice as much
U6: 2019-20 Projected
U7: Reported
A8: FTES Data | B8: 2016-17 FTES | E8: Inmates in Correctional Facilities Education FTES | F8: Special Admit FTES | G8: Excluding Inmates and Special Admit | I8: 2017-18 FTES | L8: Inmates in Correctional Facilities Education FTES | M8: Special Admit FTES | N8: Excluding Inmates and Special Admit | O8: 2018-19 FTES | R8: Inmates in Correctional Facilities Education FTES | S8: Special Admit FTES | T8: Excluding Inmates and Special Admit | U8: Credit FTES | V8: FTES Noncredit Including growth FTES | W8: FTES CDCP including growth | X8: Inmates in Correctional Facilities Education FTES | Y8: Special Admit FTES | Z8: Excluding Inmates and Special Admit
A9: District | B9: Credit | C9: Noncredit | D9: CDCP | E9: Credit | F9: Credit | G9: Credit | I9: Credit | J9: Noncredit | K9: CDCP | L9: Credit | M9: Credit | N9: Credit | O9: Reported Credit FTES | P9: FTES Noncredit Including growth FTES | Q9: FTES CDCP including growth | T9: Credit
A11: =[9]NamesDistrictCollegeCenter!B11 -> Allan Hancock Joint CCD | B11: 9202.61 | C11: 499.92 | D11: 319.04 | E11: 106.5 | F11: 425.76 | G11: =B11-E11-F11 -> 8670.35 | I11: 7860.16 | J11: 431.7 | K11: 261.7 | L11: 83.47 | M11: 436.82 | N11: =I11-L11-M11 -> 7339.87 | O11: 8984.08 | P11: 401.82 | Q11: 255.44 | R11: 73.67 | S11: 420.1 | T11: =O11-R11-S11 -> 8490.31 | U11: =IF(((((I11-B11)+(2*(O11-I11)))/3)+O11)>0,((((I11-B11)+(2*(O11-I11)))/3)+O11),O11) -> 9285.8767 | V11: =IF(((((J11-C11)+(2*(P11-J11)))/3)+P11)>0,((((J11-C11)+(2*(P11-J11)))/3)+P11),P11) -> 359.16 | W11: =IF(((((K11-D11)+(2*(Q11-K11)))/3)+Q11)>0,((((K11-D11)+(2*(Q11-K11)))/3)+Q11),Q11) -> 232.15333 | X11: =IF(((((L11-E11)+(2*(R11-L11)))/3)+R11)>0,((((L11-E11)+(2*(R11-L11)))/3)+R11),R11) -> 59.46 | Y11: =IF(((((M11-F11)+(2*(S11-M11)))/3)+S11)>0,((((M11-F11)+(2*(S11-M11)))/3)+S11),S11) -> 412.64 | Z11: =IF(((((N11-G11)+(2*(T11-N11)))/3)+T11)>0,((((N11-G11)+(2*(T11-N11)))/3)+T11),T11) -> 8813.7767
A12: =[9]NamesDistrictCollegeCenter!B12 -> Antelope Valley CCD | B12: 10523.45 | C12: 4.5 | D12: 39.28 | E12: 8.68 | F12: 302.6 | G12: =B12-E12-F12 -> 10212.17 | I12: 10527.04 | J12: 7.919966 | K12: 80.880058 | L12: 1.79 | M12: 308.01 | N12: =I12-L12-M12 -> 10217.24 | O12: 10968.8 | P12: 7.61 | Q12: 55.1 | R12: 11.01 | S12: 341.84 | T12: =O12-R12-S12 -> 10615.95 | U12: =IF(((((I12-B12)+(2*(O12-I12)))/3)+O12)>0,((((I12-B12)+(2*(O12-I12)))/3)+O12),O12) -> 11264.503 | V12: =IF(((((J12-C12)+(2*(P12-J12)))/3)+P12)>0,((((J12-C12)+(2*(P12-J12)))/3)+P12),P12) -> 8.5433447 | W12: =IF(((((K12-D12)+(2*(Q12-K12)))/3)+Q12)>0,((((K12-D12)+(2*(Q12-K12)))/3)+Q12),Q12) -> 51.779981 | X12: =IF(((((L12-E12)+(2*(R12-L12)))/3)+R12)>0,((((L12-E12)+(2*(R12-L12)))/3)+R12),R12) -> 14.86 | Y12: =IF(((((M12-F12)+(2*(S12-M12)))/3)+S12)>0,((((M12-F12)+(2*(S12-M12)))/3)+S12),S12) -> 366.19667 | Z12: =IF(((((N12-G12)+(2*(T12-N12)))/3)+T12)>0,((((N12-G12)+(2*(T12-N12)))/3)+T12),T12) -> 10883.447
