Workbook

Sheet READ ME
B1: Blue indicates raw data
B2: Indicates projected estimates
B3: Rate Assumptions
B4: Allocation Calculations

Sheet 2019-20 Rates
C1: Calculated with data available as of October 10, 2019
A2: EdCode | B2: 84750.4(b)(2) | C2: 2019-20 TCR by DOF at Budget Act | E2: 7430429651
A4: Budget Act 2019 | B4: Provision 2(a)(1) | C4: Growth | E4: 24727000 | F4: UNCLEAR WHERE THESE COME FROM
A5: EdCode | B5: 84750.4(b)(2) | C5: Hold Harmless - DOF | E5: 1.2230507e+08 | F5: UNCLEAR WHERE THESE COME FROM | G5: =22214518+121403827 -> 143618345
A6: EdCode | B6: 84750.4(b)(1) | C6: Cost of CDCP FTES | E6: 216366451 | F6: ="Calculated as " & TEXT('Base Allocation'!AB80, "###,###,###") & " using $5,313 growth at COLA (2.71%, 3.26%)" -> Calculated as 222,214,518 using $5,313 growth at COLA (2.71%, 3.26%)
A7: EdCode | B7: 84750.4(b)(1) | C7: Cost of Noncredit FTES | E7: 110682048 | F7: ="Calculated as " & TEXT('Base Allocation'!AA80, "###,###,###") & " using $3,259 growth at COLA (2.71%, 3.26%)" -> Calculated as 121,403,827 using $3,259 growth at COLA (2.71%, 3.26%)
C8: subtotal | E8: =SUM(E4:E7) -> 4.7408057e+08
C10: Funds Available for Distribution | E10: =E2-E8 -> 6.9563491e+09
A12: EdCode | B12: 84750.4(b)(2)(A) | C12: Base Allocation | D12: 0.7 | E12: =ROUND(D12*E10,0) -> 4869444357
A13: EdCode | B13: 84750.4(b)(2)(B) | C13: Supplemental Allocation | D13: 0.2 | E13: =ROUND(D13*E10,0) -> 1391269816
A14: EdCode | B14: 84750.4(b)(2)(C)(i) | C14: Student Success Allocation | D14: 0.1 | E14: =ROUND(D14*E10,0) -> 695634908
C15: =C10 -> Funds Available for Distribution | E15: =SUM(E12:E14) -> 6956349081
C17: =C12 -> Base Allocation | E17: =E12 -> 4869444357
C19: Cost of Basic Allocation | E19: 620217582 | F19: ="Calculated as " & TEXT('Base Allocation'!$AD$77, "$###,###,###,###") -> Calculated as $628,729,878
A20: EdCode | B20: 84750.4(d)(3) | C20: Cost of Incarcerated Students | E20: 25634535 | F20: ="Calculated as " & TEXT('Base Allocation'!W80, "###,###,###") & " using $5,313 growth at COLA (2.71%, 3.26%)" -> Calculated as 28,276,764 using $5,313 growth at COLA (2.71%, 3.26%)
A21: EdCode | B21: 84750.4(d)(3) | C21: Cost of Special Admit Students | E21: 205252980 | F21: ="Calculated as " & TEXT('Base Allocation'!X80, "###,###,###") & " using $5,313 growth at COLA (2.71%, 3.26%)" -> Calculated as 202,119,426 using $5,313 growth at COLA (2.71%, 3.26%)
C22: subtotal | E22: =SUM(E19:E21) -> 851105097 | F22: =TEXT(SUM('Base Allocation'!$AD$77, 'Base Allocation'!W80, 'Base Allocation'!X80), "$###,###,###,###") -> $859,126,069
C24: Funds for New Credit FTES Rate | E24: =E17-E22 -> 4018339260
C25: 3 year average Credit FTES | E25: 1007459.6 | F25: ="Calculated as "& TEXT('Base Allocation'!$Z$77, "###,###,###,###") -> Calculated as 1,003,322 | G25: 2018-19 | H25: dif | I25: %dif
A26: EdCode | B26: 84750.4(d)(1)(C)(ii) | C26: New Credit FTES Rate | E26: =E24/E25 -> 3988.5862 | G26: 3727 | H26: =E26-G26 -> 261.58618 | I26: =H26/G26 -> 0.070186793
C28: Supplemental Allocation | E28: =E13 -> 1391269816
A29: EdCode | B29: 84750.4(b)(2)(C)(i)(ii) | C29: Total Point Count | E29: =G53 -> 1496683 | F29: ="Calculated as " & TEXT(SUM('Supplemental Allocation'!K76, 'Supplemental Allocation'!L76, 'Supplemental Allocation'!M76), "###,###,###,###") -> Calculated as 1,471,229
C30: New Supplemental Allocation Point Value | E30: =E28/E29 -> 929.5688 | G30: 919 | H30: =E30-G30 -> 10.568797 | I30: =H30/G30 -> 0.011500323
C32: =C14 -> Student Success Allocation | E32: =E14 -> 695634908
C34: Main Component | D34: 0.75 | E34: =ROUND(D34*E32,0) -> 521726181
C35: Equity Component | D35: 0.25 | E35: =ROUND(D35*E32,0) -> 173908727
E36: =SUM(E34:E35) -> 695634908
C38: Main Component | E38: =E34 -> 521726181
C39: Point Count for Main Component | E39: =G72 -> 910614.17 | F39: ="Calculated as " & TEXT('Success Allocation'!$DA$80, "###,###,###,###") -> Calculated as 1,019,057 | G39: ='Success Allocation'!$DA$80 -> 1019056.5
C40: New Main Component Point Value | E40: =IF(E39>0,(E38/E39),0) -> 572.93879 | G40: 440 | H40: =E40-G40 -> 132.93879 | I40: =H40/G40 -> 0.30213362
C42: Equity Component | E42: =E35 -> 173908727
C43: Point Count for Equity Component | E43: =G89+G100 -> 1204471.3 | F43: ="Calculated as " & TEXT('Success Allocation'!$DI$80+'Success Allocation'!$DQ$80, "###,###,###,###") -> Calculated as 1,430,928
C44: New Equity Component Point Value | E44: =IF(E43>0,(E42/E43),0) -> 144.38595 | G44: 111 | H44: =E44-G44 -> 33.385951 | I44: =H44/G44 -> 0.30077433
C46: Supplemental
E48: Points | F48: Total Counts1 | G48: Total Points | H48: Total Dollars
C49: Metrics | E49: (a) | F49: (b) | G49: (c) = (a) * (b) | H49: =CONCATENATE("(d) = (c) * $",TEXT(E55,"#,###")) -> (d) = (c) * $930
C50: AB 540 Students | E50: 1 | F50: ='[1]720| Supplemental Data'!B83 -> 59199 | G50: =F50*E50 -> 59199 | H50: =G50*$E$55 -> 55029543
C51: Pell Grant Recipients | E51: 1 | F51: ='[1]720| Supplemental Data'!C83 -> 448958 | G51: =F51*E51 -> 448958 | H51: =G51*$E$55 -> 4.1733735e+08
C52: Promise Grant Recipients | E52: 1 | F52: ='[1]720| Supplemental Data'!D83 -> 988526 | G52: =F52*E52 -> 988526 | H52: =G52*$E$55 -> 9.1890292e+08
C53: Total | E53: =SUM(E50:E52) -> 3 | F53: =SUM(F50:F52) -> 1496683 | G53: =SUM(G50:G52) -> 1496683 | H53: =SUM(H50:H52) -> 1391269816
...

Sheet Rate Assumptions
A1: Count | B1: Rate | C1: Notes
A2: Credit FTES | B2: ='2019-20 Rates'!E26 -> 3988.5862 | C2: Need to verify
A3: Noncredit FTES | B3: 3456.4415 | C3: Used value from 2017-18 grown at COLA
A4: CDCP FTES | B4: 5634.5606 | C4: Used value from 2017-18 grown at COLA
A5: Special Admits and Students in Correctional Facilities FTES | B5: =B4 -> 5634.5606 | C5: Used value from 2017-18 grown at COLA
A6: Pell Grant Recipients | B6: ='2019-20 Rates'!$E$30*'2019-20 Rates'!E51 -> 929.5688 | C6: Need to verify
A7: AB 540 Students | B7: ='2019-20 Rates'!$E$30*'2019-20 Rates'!E50 -> 929.5688 | C7: Need to verify
A8: Promise Grant Recipients | B8: ='2019-20 Rates'!$E$30*'2019-20 Rates'!E52 -> 929.5688 | C8: Need to verify
A9: Associate Degrees for Transfers | B9: ='2019-20 Rates'!$E$74*'2019-20 Rates'!E64 -> 2291.7552 | C9: Need to verify
A10: Associate Degrees | B10: ='2019-20 Rates'!$E$74*'2019-20 Rates'!E65 -> 1718.8164 | C10: Need to verify
A11: Baccalaureate Degrees | B11: ='2019-20 Rates'!$E$74*'2019-20 Rates'!E66 -> 1718.8164 | C11: Need to verify
A12: Credit Certificates | B12: ='2019-20 Rates'!$E$74*'2019-20 Rates'!E67 -> 1145.8776 | C12: Need to verify
A13: Transfer Level Math and English | B13: ='2019-20 Rates'!$E$74*'2019-20 Rates'!E68 -> 1145.8776 | C13: Need to verify
A14: Transfers | B14: ='2019-20 Rates'!$E$74*'2019-20 Rates'!E69 -> 859.40819 | C14: Need to verify
A15: Nine or More CTE Units | B15: ='2019-20 Rates'!$E$74*'2019-20 Rates'!E70 -> 572.93879 | C15: Need to verify
A16: Regional Living Wage | B16: ='2019-20 Rates'!$E$74*'2019-20 Rates'!E71 -> 572.93879 | C16: Need to verify
A17: Associate Degrees for Transfers PELL GRANT | B17: ='2019-20 Rates'!$E$102*'2019-20 Rates'!E81 -> 866.31571 | C17: Need to verify
A18: Associate Degrees PELL GRANT | B18: ='2019-20 Rates'!$E$102*'2019-20 Rates'!E82 -> 649.73678 | C18: Need to verify
A19: Baccalaureate Degrees PELL GRANT | B19: ='2019-20 Rates'!$E$102*'2019-20 Rates'!E83 -> 649.73678 | C19: Need to verify
A20: Credit Certificates PELL GRANT | B20: ='2019-20 Rates'!$E$102*'2019-20 Rates'!E84 -> 433.15785 | C20: Need to verify
A21: Transfer Level Math and English PELL GRANT | B21: ='2019-20 Rates'!$E$102*'2019-20 Rates'!E85 -> 433.15785 | C21: Need to verify
A22: Transfers PELL GRANT | B22: ='2019-20 Rates'!$E$102*'2019-20 Rates'!E86 -> 324.86839 | C22: Need to verify
A23: Nine or More CTE Units PELL GRANT | B23: ='2019-20 Rates'!$E$102*'2019-20 Rates'!E87 -> 216.57893 | C23: Need to verify
A24: Regional Living Wage PELL GRANT | B24: ='2019-20 Rates'!$E$102*'2019-20 Rates'!E88 -> 216.57893 | C24: Need to verify
A25: Associate Degrees for Transfers PROMISE GRANT | B25: ='2019-20 Rates'!$E$102*'2019-20 Rates'!E92 -> 577.5438 | C25: Need to verify
A26: Associate Degrees PROMISE GRANT | B26: ='2019-20 Rates'!$E$102*'2019-20 Rates'!E93 -> 433.15785 | C26: Need to verify
A27: Baccalaureate Degrees PROMISE GRANT | B27: ='2019-20 Rates'!$E$102*'2019-20 Rates'!E94 -> 433.15785 | C27: Need to verify
A28: Credit Certificates PROMISE GRANT | B28: ='2019-20 Rates'!$E$102*'2019-20 Rates'!E95 -> 288.7719 | C28: Need to verify
A29: Transfer Level Math and English PROMISE GRANT | B29: ='2019-20 Rates'!$E$102*'2019-20 Rates'!E96 -> 288.7719 | C29: Need to verify
A30: Transfers PROMISE GRANT | B30: ='2019-20 Rates'!$E$102*'2019-20 Rates'!E97 -> 216.57893 | C30: Need to verify
A31: Nine or More CTE Units PROMISE GRANT | B31: ='2019-20 Rates'!$E$102*'2019-20 Rates'!E98 -> 144.38595 | C31: Need to verify
A32: Regional Living Wage PROMISE GRANT | B32: ='2019-20 Rates'!$E$102*'2019-20 Rates'!E99 -> 144.38595 | C32: Need to verify
A33: 2017-18 COLA | B33: 0.0271 | C33: Need to verify
A34: 2018-19 COLA | B34: 0.0326 | C34: Need to verify

Sheet CALCULATIONS >>>

Sheet District Specific SCFF
A1: District | B1: Base Allocation | C1: Supplemental Allocation | D1: Success Allocation | E1: 2019-20 Total Computational Revenue (SCFF) | F1: 2017-18 Total Computational Revenue (Realized) | G1: 2017-18 COLA | H1: 2018-19 COLA | I1: 2019-20 Minimum (2017-18 Total Computational Revenue Plus 17-18 COLA plus 18-19 COLA) | J1: 2019-20 Minimum Larger Than 2019-20 Total Computation Revenue (SCFF) | K1: Hold Harmless | L1: Basic Aid Districts | M1: Hold Harmless for Non-Basic Aid Districts | N1: 2019-20 SCFF
A2: Allan Hancock | B2: =INDEX('Base Allocation'!$A$2:$AI$77,MATCH('District Specific SCFF'!$A2,'Base Allocation'!$A$2:$A$77,0),MATCH('District Specific SCFF'!B$1,'Base Allocation'!$A$2:$AI$2,0)) -> 44716892 | C2: =INDEX('Supplemental Allocation'!$A$2:$Q$76,MATCH('District Specific SCFF'!$A2,'Supplemental Allocation'!$A$2:$A$76,0),MATCH('District Specific SCFF'!C$1,'Supplemental Allocation'!$A$2:$Q$2,0)) -> 11185501 | D2: =INDEX('Success Allocation'!$A$3:$EP$76,MATCH('District Specific SCFF'!$A2,'Success Allocation'!$A$3:$A$76,0),MATCH('District Specific SCFF'!D$1,'Success Allocation'!$A$3:$EP$3,0)) -> 6696154 | E2: =SUM(B2:D2) -> 62598547 | F2: 58423221 | G2: =INDEX('Rate Assumptions'!$A$1:$C$34,MATCH('District Specific SCFF'!G$1,'Rate Assumptions'!$A$1:$A$34,0),2) -> 0.0271 | H2: =INDEX('Rate Assumptions'!$A$1:$C$34,MATCH('District Specific SCFF'!H$1,'Rate Assumptions'!$A$1:$A$34,0),2) -> 0.0326 | I2: =F2*(1+G2)*(1+H2) -> 61962702 | J2: =IF(I2>E2,"Y","") | K2: =IF(J2="",0,I2-E2) -> 0 | M2: =IF(L2="x",0,K2) -> 0 | N2: =M2+I2 -> 61962702
A3: Antelope | B3: =INDEX('Base Allocation'!$A$2:$AI$77,MATCH('District Specific SCFF'!$A3,'Base Allocation'!$A$2:$A$77,0),MATCH('District Specific SCFF'!B$1,'Base Allocation'!$A$2:$AI$2,0)) -> 51379024 | C3: =INDEX('Supplemental Allocation'!$A$2:$Q$76,MATCH('District Specific SCFF'!$A3,'Supplemental Allocation'!$A$2:$A$76,0),MATCH('District Specific SCFF'!C$1,'Supplemental Allocation'!$A$2:$Q$2,0)) -> 21023128 | D3: =INDEX('Success Allocation'!$A$3:$EP$76,MATCH('District Specific SCFF'!$A3,'Success Allocation'!$A$3:$A$76,0),MATCH('District Specific SCFF'!D$1,'Success Allocation'!$A$3:$EP$3,0)) -> 8031644.8 | E3: =SUM(B3:D3) -> 80433796 | F3: 62613062 | G3: =INDEX('Rate Assumptions'!$A$1:$C$34,MATCH('District Specific SCFF'!G$1,'Rate Assumptions'!$A$1:$A$34,0),2) -> 0.0271 | H3: =INDEX('Rate Assumptions'!$A$1:$C$34,MATCH('District Specific SCFF'!H$1,'Rate Assumptions'!$A$1:$A$34,0),2) -> 0.0326 | I3: =F3*(1+G3)*(1+H3) -> 66406378 | J3: =IF(I3>E3,"Y","") | K3: =IF(J3="",0,I3-E3) -> 0 | M3: =IF(L3="x",0,K3) -> 0 | N3: =M3+I3 -> 66406378
A4: Barstow | B4: =INDEX('Base Allocation'!$A$2:$AI$77,MATCH('District Specific SCFF'!$A4,'Base Allocation'!$A$2:$A$77,0),MATCH('District Specific SCFF'!B$1,'Base Allocation'!$A$2:$AI$2,0)) -> 15360163 | C4: =INDEX('Supplemental Allocation'!$A$2:$Q$76,MATCH('District Specific SCFF'!$A4,'Supplemental Allocation'!$A$2:$A$76,0),MATCH('District Specific SCFF'!C$1,'Supplemental Allocation'!$A$2:$Q$2,0)) -> 4858856.1 | D4: =INDEX('Success Allocation'!$A$3:$EP$76,MATCH('District Specific SCFF'!$A4,'Success Allocation'!$A$3:$A$76,0),MATCH('District Specific SCFF'!D$1,'Success Allocation'!$A$3:$EP$3,0)) -> 2240168.5 | E4: =SUM(B4:D4) -> 22459188 | F4: 18681460 | G4: =INDEX('Rate Assumptions'!$A$1:$C$34,MATCH('District Specific SCFF'!G$1,'Rate Assumptions'!$A$1:$A$34,0),2) -> 0.0271 | H4: =INDEX('Rate Assumptions'!$A$1:$C$34,MATCH('District Specific SCFF'!H$1,'Rate Assumptions'!$A$1:$A$34,0),2) -> 0.0326 | I4: =F4*(1+G4)*(1+H4) -> 19813247 | J4: =IF(I4>E4,"Y","") | K4: =IF(J4="",0,I4-E4) -> 0 | M4: =IF(L4="x",0,K4) -> 0 | N4: =M4+I4 -> 19813247
A5: Butte | B5: =INDEX('Base Allocation'!$A$2:$AI$77,MATCH('District Specific SCFF'!$A5,'Base Allocation'!$A$2:$A$77,0),MATCH('District Specific SCFF'!B$1,'Base Allocation'!$A$2:$AI$2,0)) -> 48029964 | C5: =INDEX('Supplemental Allocation'!$A$2:$Q$76,MATCH('District Specific SCFF'!$A5,'Supplemental Allocation'!$A$2:$A$76,0),MATCH('District Specific SCFF'!C$1,'Supplemental Allocation'!$A$2:$Q$2,0)) -> 12047212 | D5: =INDEX('Success Allocation'!$A$3:$EP$76,MATCH('District Specific SCFF'!$A5,'Success Allocation'!$A$3:$A$76,0),MATCH('District Specific SCFF'!D$1,'Success Allocation'!$A$3:$EP$3,0)) -> 8115842.2 | E5: =SUM(B5:D5) -> 68193017 | F5: 58869732 | G5: =INDEX('Rate Assumptions'!$A$1:$C$34,MATCH('District Specific SCFF'!G$1,'Rate Assumptions'!$A$1:$A$34,0),2) -> 0.0271 | H5: =INDEX('Rate Assumptions'!$A$1:$C$34,MATCH('District Specific SCFF'!H$1,'Rate Assumptions'!$A$1:$A$34,0),2) -> 0.0326 | I5: =F5*(1+G5)*(1+H5) -> 62436264 | J5: =IF(I5>E5,"Y","") | K5: =IF(J5="",0,I5-E5) -> 0 | M5: =IF(L5="x",0,K5) -> 0 | N5: =M5+I5 -> 62436264
A6: Cabrillo | B6: =INDEX('Base Allocation'!$A$2:$AI$77,MATCH('District Specific SCFF'!$A6,'Base Allocation'!$A$2:$A$77,0),MATCH('District Specific SCFF'!B$1,'Base Allocation'!$A$2:$AI$2,0)) -> 47678619 | C6: =INDEX('Supplemental Allocation'!$A$2:$Q$76,MATCH('District Specific SCFF'!$A6,'Supplemental Allocation'!$A$2:$A$76,0),MATCH('District Specific SCFF'!C$1,'Supplemental Allocation'!$A$2:$Q$2,0)) -> 8852283.7 | D6: =INDEX('Success Allocation'!$A$3:$EP$76,MATCH('District Specific SCFF'!$A6,'Success Allocation'!$A$3:$A$76,0),MATCH('District Specific SCFF'!D$1,'Success Allocation'!$A$3:$EP$3,0)) -> 6160625.2 | E6: =SUM(B6:D6) -> 62691528 | F6: 61066687 | G6: =INDEX('Rate Assumptions'!$A$1:$C$34,MATCH('District Specific SCFF'!G$1,'Rate Assumptions'!$A$1:$A$34,0),2) -> 0.0271 | H6: =INDEX('Rate Assumptions'!$A$1:$C$34,MATCH('District Specific SCFF'!H$1,'Rate Assumptions'!$A$1:$A$34,0),2) -> 0.0326 | I6: =F6*(1+G6)*(1+H6) -> 64766318 | J6: =IF(I6>E6,"Y","") -> Y | K6: =IF(J6="",0,I6-E6) -> 2074789.8 | M6: =IF(L6="x",0,K6) -> 2074789.8 | N6: =M6+I6 -> 66841108
A7: Cerritos | B7: =INDEX('Base Allocation'!$A$2:$AI$77,MATCH('District Specific SCFF'!$A7,'Base Allocation'!$A$2:$A$77,0),MATCH('District Specific SCFF'!B$1,'Base Allocation'!$A$2:$AI$2,0)) -> 71743529 | C7: =INDEX('Supplemental Allocation'!$A$2:$Q$76,MATCH('District Specific SCFF'!$A7,'Supplemental Allocation'!$A$2:$A$76,0),MATCH('District Specific SCFF'!C$1,'Supplemental Allocation'!$A$2:$Q$2,0)) -> 27395322 | D7: =INDEX('Success Allocation'!$A$3:$EP$76,MATCH('District Specific SCFF'!$A7,'Success Allocation'!$A$3:$A$76,0),MATCH('District Specific SCFF'!D$1,'Success Allocation'!$A$3:$EP$3,0)) -> 13540953 | E7: =SUM(B7:D7) -> 1.126798e+08 | F7: 93447643 | G7: =INDEX('Rate Assumptions'!$A$1:$C$34,MATCH('District Specific SCFF'!G$1,'Rate Assumptions'!$A$1:$A$34,0),2) -> 0.0271 | H7: =INDEX('Rate Assumptions'!$A$1:$C$34,MATCH('District Specific SCFF'!H$1,'Rate Assumptions'!$A$1:$A$34,0),2) -> 0.0326 | I7: =F7*(1+G7)*(1+H7) -> 99109025 | J7: =IF(I7>E7,"Y","") | K7: =IF(J7="",0,I7-E7) -> 0 | M7: =IF(L7="x",0,K7) -> 0 | N7: =M7+I7 -> 99109025
A8: Chabot-Las Positas | B8: =INDEX('Base Allocation'!$A$2:$AI$77,MATCH('District Specific SCFF'!$A8,'Base Allocation'!$A$2:$A$77,0),MATCH('District Specific SCFF'!B$1,'Base Allocation'!$A$2:$AI$2,0)) -> 74184208 | C8: =INDEX('Supplemental Allocation'!$A$2:$Q$76,MATCH('District Specific SCFF'!$A8,'Supplemental Allocation'!$A$2:$A$76,0),MATCH('District Specific SCFF'!C$1,'Supplemental Allocation'!$A$2:$Q$2,0)) -> 15302562 | D8: =INDEX('Success Allocation'!$A$3:$EP$76,MATCH('District Specific SCFF'!$A8,'Success Allocation'!$A$3:$A$76,0),MATCH('District Specific SCFF'!D$1,'Success Allocation'!$A$3:$EP$3,0)) -> 11525159 | E8: =SUM(B8:D8) -> 1.0101193e+08 | F8: 107679794 | G8: =INDEX('Rate Assumptions'!$A$1:$C$34,MATCH('District Specific SCFF'!G$1,'Rate Assumptions'!$A$1:$A$34,0),2) -> 0.0271 | H8: =INDEX('Rate Assumptions'!$A$1:$C$34,MATCH('District Specific SCFF'!H$1,'Rate Assumptions'!$A$1:$A$34,0),2) -> 0.0326 | I8: =F8*(1+G8)*(1+H8) -> 1.1420341e+08 | J8: =IF(I8>E8,"Y","") -> Y | K8: =IF(J8="",0,I8-E8) -> 13191480 | M8: =IF(L8="x",0,K8) -> 13191480 | N8: =M8+I8 -> 1.2739489e+08
A9: Chaffey | B9: =INDEX('Base Allocation'!$A$2:$AI$77,MATCH('District Specific SCFF'!$A9,'Base Allocation'!$A$2:$A$77,0),MATCH('District Specific SCFF'!B$1,'Base Allocation'!$A$2:$AI$2,0)) -> 74314293 | C9: =INDEX('Supplemental Allocation'!$A$2:$Q$76,MATCH('District Specific SCFF'!$A9,'Supplemental Allocation'!$A$2:$A$76,0),MATCH('District Specific SCFF'!C$1,'Supplemental Allocation'!$A$2:$Q$2,0)) -> 25822492 | D9: =INDEX('Success Allocation'!$A$3:$EP$76,MATCH('District Specific SCFF'!$A9,'Success Allocation'!$A$3:$A$76,0),MATCH('District Specific SCFF'!D$1,'Success Allocation'!$A$3:$EP$3,0)) -> 12928519 | E9: =SUM(B9:D9) -> 1.130653e+08 | F9: 93669819 | G9: =INDEX('Rate Assumptions'!$A$1:$C$34,MATCH('District Specific SCFF'!G$1,'Rate Assumptions'!$A$1:$A$34,0),2) -> 0.0271 | H9: =INDEX('Rate Assumptions'!$A$1:$C$34,MATCH('District Specific SCFF'!H$1,'Rate Assumptions'!$A$1:$A$34,0),2) -> 0.0326 | I9: =F9*(1+G9)*(1+H9) -> 99344661 | J9: =IF(I9>E9,"Y","") | K9: =IF(J9="",0,I9-E9) -> 0 | M9: =IF(L9="x",0,K9) -> 0 | N9: =M9+I9 -> 99344661
A10: Citrus | B10: =INDEX('Base Allocation'!$A$2:$AI$77,MATCH('District Specific SCFF'!$A10,'Base Allocation'!$A$2:$A$77,0),MATCH('District Specific SCFF'!B$1,'Base Allocation'!$A$2:$AI$2,0)) -> 52374517 | C10: =INDEX('Supplemental Allocation'!$A$2:$Q$76,MATCH('District Specific SCFF'!$A10,'Supplemental Allocation'!$A$2:$A$76,0),MATCH('District Specific SCFF'!C$1,'Supplemental Allocation'!$A$2:$Q$2,0)) -> 15639995 | D10: =INDEX('Success Allocation'!$A$3:$EP$76,MATCH('District Specific SCFF'!$A10,'Success Allocation'!$A$3:$A$76,0),MATCH('District Specific SCFF'!D$1,'Success Allocation'!$A$3:$EP$3,0)) -> 9994418.3 | E10: =SUM(B10:D10) -> 78008930 | F10: 68139191 | G10: =INDEX('Rate Assumptions'!$A$1:$C$34,MATCH('District Specific SCFF'!G$1,'Rate Assumptions'!$A$1:$A$34,0),2) -> 0.0271 | H10: =INDEX('Rate Assumptions'!$A$1:$C$34,MATCH('District Specific SCFF'!H$1,'Rate Assumptions'!$A$1:$A$34,0),2) -> 0.0326 | I10: =F10*(1+G10)*(1+H10) -> 72267299 | J10: =IF(I10>E10,"Y","") | K10: =IF(J10="",0,I10-E10) -> 0 | M10: =IF(L10="x",0,K10) -> 0 | N10: =M10+I10 -> 72267299
A11: Coast | B11: =INDEX('Base Allocation'!$A$2:$AI$77,MATCH('District Specific SCFF'!$A11,'Base Allocation'!$A$2:$A$77,0),MATCH('District Specific SCFF'!B$1,'Base Allocation'!$A$2:$AI$2,0)) -> 1.3933535e+08 | C11: =INDEX('Supplemental Allocation'!$A$2:$Q$76,MATCH('District Specific SCFF'!$A11,'Supplemental Allocation'!$A$2:$A$76,0),MATCH('District Specific SCFF'!C$1,'Supplemental Allocation'!$A$2:$Q$2,0)) -> 41733921 | D11: =INDEX('Success Allocation'!$A$3:$EP$76,MATCH('District Specific SCFF'!$A11,'Success Allocation'!$A$3:$A$76,0),MATCH('District Specific SCFF'!D$1,'Success Allocation'!$A$3:$EP$3,0)) -> 26702605 | E11: =SUM(B11:D11) -> 2.0777187e+08 | F11: 184284255 | G11: =INDEX('Rate Assumptions'!$A$1:$C$34,MATCH('District Specific SCFF'!G$1,'Rate Assumptions'!$A$1:$A$34,0),2) -> 0.0271 | H11: =INDEX('Rate Assumptions'!$A$1:$C$34,MATCH('District Specific SCFF'!H$1,'Rate Assumptions'!$A$1:$A$34,0),2) -> 0.0326 | I11: =F11*(1+G11)*(1+H11) -> 1.9544883e+08 | J11: =IF(I11>E11,"Y","") | K11: =IF(J11="",0,I11-E11) -> 0 | M11: =IF(L11="x",0,K11) -> 0 | N11: =M11+I11 -> 1.9544883e+08
A12: Compton | B12: =INDEX('Base Allocation'!$A$2:$AI$77,MATCH('District Specific SCFF'!$A12,'Base Allocation'!$A$2:$A$77,0),MATCH('District Specific SCFF'!B$1,'Base Allocation'!$A$2:$AI$2,0)) -> 28723234 | C12: =INDEX('Supplemental Allocation'!$A$2:$Q$76,MATCH('District Specific SCFF'!$A12,'Supplemental Allocation'!$A$2:$A$76,0),MATCH('District Specific SCFF'!C$1,'Supplemental Allocation'!$A$2:$Q$2,0)) -> 6404729 | D12: =INDEX('Success Allocation'!$A$3:$EP$76,MATCH('District Specific SCFF'!$A12,'Success Allocation'!$A$3:$A$76,0),MATCH('District Specific SCFF'!D$1,'Success Allocation'!$A$3:$EP$3,0)) -> 2952104.9 | E12: =SUM(B12:D12) -> 38080068 | F12: 35475170 | G12: =INDEX('Rate Assumptions'!$A$1:$C$34,MATCH('District Specific SCFF'!G$1,'Rate Assumptions'!$A$1:$A$34,0),2) -> 0.0271 | H12: =INDEX('Rate Assumptions'!$A$1:$C$34,MATCH('District Specific SCFF'!H$1,'Rate Assumptions'!$A$1:$A$34,0),2) -> 0.0326 | I12: =F12*(1+G12)*(1+H12) -> 37624379 | J12: =IF(I12>E12,"Y","") | K12: =IF(J12="",0,I12-E12) -> 0 | M12: =IF(L12="x",0,K12) -> 0 | N12: =M12+I12 -> 37624379
A13: Contra Costa | B13: =INDEX('Base Allocation'!$A$2:$AI$77,MATCH('District Specific SCFF'!$A13,'Base Allocation'!$A$2:$A$77,0),MATCH('District Specific SCFF'!B$1,'Base Allocation'!$A$2:$AI$2,0)) -> 1.2211645e+08 | C13: =INDEX('Supplemental Allocation'!$A$2:$Q$76,MATCH('District Specific SCFF'!$A13,'Supplemental Allocation'!$A$2:$A$76,0),MATCH('District Specific SCFF'!C$1,'Supplemental Allocation'!$A$2:$Q$2,0)) -> 26033504 | D13: =INDEX('Success Allocation'!$A$3:$EP$76,MATCH('District Specific SCFF'!$A13,'Success Allocation'!$A$3:$A$76,0),MATCH('District Specific SCFF'!D$1,'Success Allocation'!$A$3:$EP$3,0)) -> 19911652 | E13: =SUM(B13:D13) -> 1.680616e+08 | F13: 170246475 | G13: =INDEX('Rate Assumptions'!$A$1:$C$34,MATCH('District Specific SCFF'!G$1,'Rate Assumptions'!$A$1:$A$34,0),2) -> 0.0271 | H13: =INDEX('Rate Assumptions'!$A$1:$C$34,MATCH('District Specific SCFF'!H$1,'Rate Assumptions'!$A$1:$A$34,0),2) -> 0.0326 | I13: =F13*(1+G13)*(1+H13) -> 1.805606e+08 | J13: =IF(I13>E13,"Y","") -> Y | K13: =IF(J13="",0,I13-E13) -> 12498994 | M13: =IF(L13="x",0,K13) -> 12498994 | N13: =M13+I13 -> 1.9305959e+08
... A29: Los Rios | B29: =INDEX('Base Allocation'!$A$2:$AI$77,MATCH('District Specific SCFF'!$A29,'Base Allocation'!$A$2:$A$77,0),MATCH('District Specific SCFF'!B$1,'Base Allocation'!$A$2:$AI$2,0)) -> 2.2943937e+08 | C29: =INDEX('Supplemental Allocation'!$A$2:$Q$76,MATCH('District Specific SCFF'!$A29,'Supplemental Allocation'!$A$2:$A$76,0),MATCH('District Specific SCFF'!C$1,'Supplemental Allocation'!$A$2:$Q$2,0)) -> 66255946 | D29: =INDEX('Success Allocation'!$A$3:$EP$76,MATCH('District Specific SCFF'!$A29,'Success Allocation'!$A$3:$A$76,0),MATCH('District Specific SCFF'!D$1,'Success Allocation'!$A$3:$EP$3,0)) -> 36722101 | E29: =SUM(B29:D29) -> 3.3241742e+08 | F29: 303959995 | G29: =INDEX('Rate Assumptions'!$A$1:$C$34,MATCH('District Specific SCFF'!G$1,'Rate Assumptions'!$A$1:$A$34,0),2) -> 0.0271 | H29: =INDEX('Rate Assumptions'!$A$1:$C$34,MATCH('District Specific SCFF'!H$1,'Rate Assumptions'!$A$1:$A$34,0),2) -> 0.0326 | I29: =F29*(1+G29)*(1+H29) -> 3.2237494e+08 | J29: =IF(I29>E29,"Y","") | K29: =IF(J29="",0,I29-E29) -> 0 | M29: =IF(L29="x",0,K29) -> 0 | N29: =M29+I29 -> 3.2237494e+08
A30: Marin | B30: =INDEX('Base Allocation'!$A$2:$AI$77,MATCH('District Specific SCFF'!$A30,'Base Allocation'!$A$2:$A$77,0),MATCH('District Specific SCFF'!B$1,'Base Allocation'!$A$2:$AI$2,0)) -> 17663150 | C30: =INDEX('Supplemental Allocation'!$A$2:$Q$76,MATCH('District Specific SCFF'!$A30,'Supplemental Allocation'!$A$2:$A$76,0),MATCH('District Specific SCFF'!C$1,'Supplemental Allocation'!$A$2:$Q$2,0)) -> 2930930.4 | D30: =INDEX('Success Allocation'!$A$3:$EP$76,MATCH('District Specific SCFF'!$A30,'Success Allocation'!$A$3:$A$76,0),MATCH('District Specific SCFF'!D$1,'Success Allocation'!$A$3:$EP$3,0)) -> 1872784.4 | E30: =SUM(B30:D30) -> 22466865 | F30: 25606935 | G30: =INDEX('Rate Assumptions'!$A$1:$C$34,MATCH('District Specific SCFF'!G$1,'Rate Assumptions'!$A$1:$A$34,0),2) -> 0.0271 | H30: =INDEX('Rate Assumptions'!$A$1:$C$34,MATCH('District Specific SCFF'!H$1,'Rate Assumptions'!$A$1:$A$34,0),2) -> 0.0326 | I30: =F30*(1+G30)*(1+H30) -> 27158292 | J30: =IF(I30>E30,"Y","") -> Y | K30: =IF(J30="",0,I30-E30) -> 4691426.5 | L30: x | M30: =IF(L30="x",0,K30) -> 0 | N30: =M30+I30 -> 27158292
A31: Mendocino | B31: =INDEX('Base Allocation'!$A$2:$AI$77,MATCH('District Specific SCFF'!$A31,'Base Allocation'!$A$2:$A$77,0),MATCH('District Specific SCFF'!B$1,'Base Allocation'!$A$2:$AI$2,0)) -> 18063757 | C31: =INDEX('Supplemental Allocation'!$A$2:$Q$76,MATCH('District Specific SCFF'!$A31,'Supplemental Allocation'!$A$2:$A$76,0),MATCH('District Specific SCFF'!C$1,'Supplemental Allocation'!$A$2:$Q$2,0)) -> 3806584.2 | D31: =INDEX('Success Allocation'!$A$3:$EP$76,MATCH('District Specific SCFF'!$A31,'Success Allocation'!$A$3:$A$76,0),MATCH('District Specific SCFF'!D$1,'Success Allocation'!$A$3:$EP$3,0)) -> 2224095.4 | E31: =SUM(B31:D31) -> 24094437 | F31: 22434165 | G31: =INDEX('Rate Assumptions'!$A$1:$C$34,MATCH('District Specific SCFF'!G$1,'Rate Assumptions'!$A$1:$A$34,0),2) -> 0.0271 | H31: =INDEX('Rate Assumptions'!$A$1:$C$34,MATCH('District Specific SCFF'!H$1,'Rate Assumptions'!$A$1:$A$34,0),2) -> 0.0326 | I31: =F31*(1+G31)*(1+H31) -> 23793304 | J31: =IF(I31>E31,"Y","") | K31: =IF(J31="",0,I31-E31) -> 0 | M31: =IF(L31="x",0,K31) -> 0 | N31: =M31+I31 -> 23793304
A32: Merced | B32: =INDEX('Base Allocation'!$A$2:$AI$77,MATCH('District Specific SCFF'!$A32,'Base Allocation'!$A$2:$A$77,0),MATCH('District Specific SCFF'!B$1,'Base Allocation'!$A$2:$AI$2,0)) -> 46378425 | C32: =INDEX('Supplemental Allocation'!$A$2:$Q$76,MATCH('District Specific SCFF'!$A32,'Supplemental Allocation'!$A$2:$A$76,0),MATCH('District Specific SCFF'!C$1,'Supplemental Allocation'!$A$2:$Q$2,0)) -> 13281679 | D32: =INDEX('Success Allocation'!$A$3:$EP$76,MATCH('District Specific SCFF'!$A32,'Success Allocation'!$A$3:$A$76,0),MATCH('District Specific SCFF'!D$1,'Success Allocation'!$A$3:$EP$3,0)) -> 7814570.1 | E32: =SUM(B32:D32) -> 67474674 | F32: 56496411 | G32: =INDEX('Rate Assumptions'!$A$1:$C$34,MATCH('District Specific SCFF'!G$1,'Rate Assumptions'!$A$1:$A$34,0),2) -> 0.0271 | H32: =INDEX('Rate Assumptions'!$A$1:$C$34,MATCH('District Specific SCFF'!H$1,'Rate Assumptions'!$A$1:$A$34,0),2) -> 0.0326 | I32: =F32*(1+G32)*(1+H32) -> 59919159 | J32: =IF(I32>E32,"Y","") | K32: =IF(J32="",0,I32-E32) -> 0 | M32: =IF(L32="x",0,K32) -> 0 | N32: =M32+I32 -> 59919159
A33: MiraCosta | B33: =INDEX('Base Allocation'!$A$2:$AI$77,MATCH('District Specific SCFF'!$A33,'Base Allocation'!$A$2:$A$77,0),MATCH('District Specific SCFF'!B$1,'Base Allocation'!$A$2:$AI$2,0)) -> 46762627 | C33: =INDEX('Supplemental Allocation'!$A$2:$Q$76,MATCH('District Specific SCFF'!$A33,'Supplemental Allocation'!$A$2:$A$76,0),MATCH('District Specific SCFF'!C$1,'Supplemental Allocation'!$A$2:$Q$2,0)) -> 13171990 | D33: =INDEX('Success Allocation'!$A$3:$EP$76,MATCH('District Specific SCFF'!$A33,'Success Allocation'!$A$3:$A$76,0),MATCH('District Specific SCFF'!D$1,'Success Allocation'!$A$3:$EP$3,0)) -> 9640643.5 | E33: =SUM(B33:D33) -> 69575261 | F33: 63540067 | G33: =INDEX('Rate Assumptions'!$A$1:$C$34,MATCH('District Specific SCFF'!G$1,'Rate Assumptions'!$A$1:$A$34,0),2) -> 0.0271 | H33: =INDEX('Rate Assumptions'!$A$1:$C$34,MATCH('District Specific SCFF'!H$1,'Rate Assumptions'!$A$1:$A$34,0),2) -> 0.0326 | I33: =F33*(1+G33)*(1+H33) -> 67389544 | J33: =IF(I33>E33,"Y","") | K33: =IF(J33="",0,I33-E33) -> 0 | L33: x | M33: =IF(L33="x",0,K33) -> 0 | N33: =M33+I33 -> 67389544
A34: Monterey | B34: =INDEX('Base Allocation'!$A$2:$AI$77,MATCH('District Specific SCFF'!$A34,'Base Allocation'!$A$2:$A$77,0),MATCH('District Specific SCFF'!B$1,'Base Allocation'!$A$2:$AI$2,0)) -> 29413762 | C34: =INDEX('Supplemental Allocation'!$A$2:$Q$76,MATCH('District Specific SCFF'!$A34,'Supplemental Allocation'!$A$2:$A$76,0),MATCH('District Specific SCFF'!C$1,'Supplemental Allocation'!$A$2:$Q$2,0)) -> 7029399.2 | D34: =INDEX('Success Allocation'!$A$3:$EP$76,MATCH('District Specific SCFF'!$A34,'Success Allocation'!$A$3:$A$76,0),MATCH('District Specific SCFF'!D$1,'Success Allocation'!$A$3:$EP$3,0)) -> 5189495.9 | E34: =SUM(B34:D34) -> 41632657 | F34: 38888873 | G34: =INDEX('Rate Assumptions'!$A$1:$C$34,MATCH('District Specific SCFF'!G$1,'Rate Assumptions'!$A$1:$A$34,0),2) -> 0.0271 | H34: =INDEX('Rate Assumptions'!$A$1:$C$34,MATCH('District Specific SCFF'!H$1,'Rate Assumptions'!$A$1:$A$34,0),2) -> 0.0326 | I34: =F34*(1+G34)*(1+H34) -> 41244895 | J34: =IF(I34>E34,"Y","") | K34: =IF(J34="",0,I34-E34) -> 0 | M34: =IF(L34="x",0,K34) -> 0 | N34: =M34+I34 -> 41244895
A35: Mt. San Antonio | B35: =INDEX('Base Allocation'!$A$2:$AI$77,MATCH('District Specific SCFF'!$A35,'Base Allocation'!$A$2:$A$77,0),MATCH('District Specific SCFF'!B$1,'Base Allocation'!$A$2:$AI$2,0)) -> 1.5032963e+08 | C35: =INDEX('Supplemental Allocation'!$A$2:$Q$76,MATCH('District Specific SCFF'!$A35,'Supplemental Allocation'!$A$2:$A$76,0),MATCH('District Specific SCFF'!C$1,'Supplemental Allocation'!$A$2:$Q$2,0)) -> 35875778 | D35: =INDEX('Success Allocation'!$A$3:$EP$76,MATCH('District Specific SCFF'!$A35,'Success Allocation'!$A$3:$A$76,0),MATCH('District Specific SCFF'!D$1,'Success Allocation'!$A$3:$EP$3,0)) -> 17248770 | E35: =SUM(B35:D35) -> 2.0345418e+08 | F35: 176424297 | G35: =INDEX('Rate Assumptions'!$A$1:$C$34,MATCH('District Specific SCFF'!G$1,'Rate Assumptions'!$A$1:$A$34,0),2) -> 0.0271 | H35: =INDEX('Rate Assumptions'!$A$1:$C$34,MATCH('District Specific SCFF'!H$1,'Rate Assumptions'!$A$1:$A$34,0),2) -> 0.0326 | I35: =F35*(1+G35)*(1+H35) -> 1.8711269e+08 | J35: =IF(I35>E35,"Y","") | K35: =IF(J35="",0,I35-E35) -> 0 | M35: =IF(L35="x",0,K35) -> 0 | N35: =M35+I35 -> 1.8711269e+08
A36: Mt. San Jacinto | B36: =INDEX('Base Allocation'!$A$2:$AI$77,MATCH('District Specific SCFF'!$A36,'Base Allocation'!$A$2:$A$77,0),MATCH('District Specific SCFF'!B$1,'Base Allocation'!$A$2:$AI$2,0)) -> 53879645 | C36: =INDEX('Supplemental Allocation'!$A$2:$Q$76,MATCH('District Specific SCFF'!$A36,'Supplemental Allocation'!$A$2:$A$76,0),MATCH('District Specific SCFF'!C$1,'Supplemental Allocation'!$A$2:$Q$2,0)) -> 20307360 | D36: =INDEX('Success Allocation'!$A$3:$EP$76,MATCH('District Specific SCFF'!$A36,'Success Allocation'!$A$3:$A$76,0),MATCH('District Specific SCFF'!D$1,'Success Allocation'!$A$3:$EP$3,0)) -> 9458392.4 | E36: =SUM(B36:D36) -> 83645397 | F36: 71517436 | G36: =INDEX('Rate Assumptions'!$A$1:$C$34,MATCH('District Specific SCFF'!G$1,'Rate Assumptions'!$A$1:$A$34,0),2) -> 0.0271 | H36: =INDEX('Rate Assumptions'!$A$1:$C$34,MATCH('District Specific SCFF'!H$1,'Rate Assumptions'!$A$1:$A$34,0),2) -> 0.0326 | I36: =F36*(1+G36)*(1+H36) -> 75850210 | J36: =IF(I36>E36,"Y","") | K36: =IF(J36="",0,I36-E36) -> 0 | M36: =IF(L36="x",0,K36) -> 0 | N36: =M36+I36 -> 75850210
A37: Napa | B37: =INDEX('Base Allocation'!$A$2:$AI$77,MATCH('District Specific SCFF'!$A37,'Base Allocation'!$A$2:$A$77,0),MATCH('District Specific SCFF'!B$1,'Base Allocation'!$A$2:$AI$2,0)) -> 24652417 | C37: =INDEX('Supplemental Allocation'!$A$2:$Q$76,MATCH('District Specific SCFF'!$A37,'Supplemental Allocation'!$A$2:$A$76,0),MATCH('District Specific SCFF'!C$1,'Supplemental Allocation'!$A$2:$Q$2,0)) -> 5168402.5 | D37: =INDEX('Success Allocation'!$A$3:$EP$76,MATCH('District Specific SCFF'!$A37,'Success Allocation'!$A$3:$A$76,0),MATCH('District Specific SCFF'!D$1,'Success Allocation'!$A$3:$EP$3,0)) -> 3610585.1 | E37: =SUM(B37:D37) -> 33431405 | F37: 31620290 | G37: =INDEX('Rate Assumptions'!$A$1:$C$34,MATCH('District Specific SCFF'!G$1,'Rate Assumptions'!$A$1:$A$34,0),2) -> 0.0271 | H37: =INDEX('Rate Assumptions'!$A$1:$C$34,MATCH('District Specific SCFF'!H$1,'Rate Assumptions'!$A$1:$A$34,0),2) -> 0.0326 | I37: =F37*(1+G37)*(1+H37) -> 33535957 | J37: =IF(I37>E37,"Y","") -> Y | K37: =IF(J37="",0,I37-E37) -> 104551.55 | M37: =IF(L37="x",0,K37) -> 104551.55 | N37: =M37+I37 -> 33640508
A38: North Orange | B38: =INDEX('Base Allocation'!$A$2:$AI$77,MATCH('District Specific SCFF'!$A38,'Base Allocation'!$A$2:$A$77,0),MATCH('District Specific SCFF'!B$1,'Base Allocation'!$A$2:$AI$2,0)) -> 1.3949899e+08 | C38: =INDEX('Supplemental Allocation'!$A$2:$Q$76,MATCH('District Specific SCFF'!$A38,'Supplemental Allocation'!$A$2:$A$76,0),MATCH('District Specific SCFF'!C$1,'Supplemental Allocation'!$A$2:$Q$2,0)) -> 34860689 | D38: =INDEX('Success Allocation'!$A$3:$EP$76,MATCH('District Specific SCFF'!$A38,'Success Allocation'!$A$3:$A$76,0),MATCH('District Specific SCFF'!D$1,'Success Allocation'!$A$3:$EP$3,0)) -> 21025588 | E38: =SUM(B38:D38) -> 1.9538527e+08 | F38: 202056270 | G38: =INDEX('Rate Assumptions'!$A$1:$C$34,MATCH('District Specific SCFF'!G$1,'Rate Assumptions'!$A$1:$A$34,0),2) -> 0.0271 | H38: =INDEX('Rate Assumptions'!$A$1:$C$34,MATCH('District Specific SCFF'!H$1,'Rate Assumptions'!$A$1:$A$34,0),2) -> 0.0326 | I38: =F38*(1+G38)*(1+H38) -> 2.1429754e+08 | J38: =IF(I38>E38,"Y","") -> Y | K38: =IF(J38="",0,I38-E38) -> 18912273 | M38: =IF(L38="x",0,K38) -> 18912273 | N38: =M38+I38 -> 2.3320981e+08
A39: Ohlone | B39: =INDEX('Base Allocation'!$A$2:$AI$77,MATCH('District Specific SCFF'!$A39,'Base Allocation'!$A$2:$A$77,0),MATCH('District Specific SCFF'!B$1,'Base Allocation'!$A$2:$AI$2,0)) -> 34039372 | C39: =INDEX('Supplemental Allocation'!$A$2:$Q$76,MATCH('District Specific SCFF'!$A39,'Supplemental Allocation'!$A$2:$A$76,0),MATCH('District Specific SCFF'!C$1,'Supplemental Allocation'!$A$2:$Q$2,0)) -> 4701759 | D39: =INDEX('Success Allocation'!$A$3:$EP$76,MATCH('District Specific SCFF'!$A39,'Success Allocation'!$A$3:$A$76,0),MATCH('District Specific SCFF'!D$1,'Success Allocation'!$A$3:$EP$3,0)) -> 4914244.1 | E39: =SUM(B39:D39) -> 43655375 | F39: 48764473 | G39: =INDEX('Rate Assumptions'!$A$1:$C$34,MATCH('District Specific SCFF'!G$1,'Rate Assumptions'!$A$1:$A$34,0),2) -> 0.0271 | H39: =INDEX('Rate Assumptions'!$A$1:$C$34,MATCH('District Specific SCFF'!H$1,'Rate Assumptions'!$A$1:$A$34,0),2) -> 0.0326 | I39: =F39*(1+G39)*(1+H39) -> 51718793 | J39: =IF(I39>E39,"Y","") -> Y | K39: =IF(J39="",0,I39-E39) -> 8063418.4 | M39: =IF(L39="x",0,K39) -> 8063418.4 | N39: =M39+I39 -> 59782212
A40: Palo Verde | B40: =INDEX('Base Allocation'!$A$2:$AI$77,MATCH('District Specific SCFF'!$A40,'Base Allocation'!$A$2:$A$77,0),MATCH('District Specific SCFF'!B$1,'Base Allocation'!$A$2:$AI$2,0)) -> 14539576 | C40: =INDEX('Supplemental Allocation'!$A$2:$Q$76,MATCH('District Specific SCFF'!$A40,'Supplemental Allocation'!$A$2:$A$76,0),MATCH('District Specific SCFF'!C$1,'Supplemental Allocation'!$A$2:$Q$2,0)) -> 3393855.7 | D40: =INDEX('Success Allocation'!$A$3:$EP$76,MATCH('District Specific SCFF'!$A40,'Success Allocation'!$A$3:$A$76,0),MATCH('District Specific SCFF'!D$1,'Success Allocation'!$A$3:$EP$3,0)) -> 1241113.4 | E40: =SUM(B40:D40) -> 19174545 | F40: 16636774 | G40: =INDEX('Rate Assumptions'!$A$1:$C$34,MATCH('District Specific SCFF'!G$1,'Rate Assumptions'!$A$1:$A$34,0),2) -> 0.0271 | H40: =INDEX('Rate Assumptions'!$A$1:$C$34,MATCH('District Specific SCFF'!H$1,'Rate Assumptions'!$A$1:$A$34,0),2) -> 0.0326 | I40: =F40*(1+G40)*(1+H40) -> 17644687 | J40: =IF(I40>E40,"Y","") | K40: =IF(J40="",0,I40-E40) -> 0 | M40: =IF(L40="x",0,K40) -> 0 | N40: =M40+I40 -> 17644687
A41: Palomar | B41: =INDEX('Base Allocation'!$A$2:$AI$77,MATCH('District Specific SCFF'!$A41,'Base Allocation'!$A$2:$A$77,0),MATCH('District Specific SCFF'!B$1,'Base Allocation'!$A$2:$AI$2,0)) -> 80483849 | C41: =INDEX('Supplemental Allocation'!$A$2:$Q$76,MATCH('District Specific SCFF'!$A41,'Supplemental Allocation'!$A$2:$A$76,0),MATCH('District Specific SCFF'!C$1,'Supplemental Allocation'!$A$2:$Q$2,0)) -> 19782154 | D41: =INDEX('Success Allocation'!$A$3:$EP$76,MATCH('District Specific SCFF'!$A41,'Success Allocation'!$A$3:$A$76,0),MATCH('District Specific SCFF'!D$1,'Success Allocation'!$A$3:$EP$3,0)) -> 12323100 | E41: =SUM(B41:D41) -> 1.125891e+08 | F41: 108548444 | G41: =INDEX('Rate Assumptions'!$A$1:$C$34,MATCH('District Specific SCFF'!G$1,'Rate Assumptions'!$A$1:$A$34,0),2) -> 0.0271 | H41: =INDEX('Rate Assumptions'!$A$1:$C$34,MATCH('District Specific SCFF'!H$1,'Rate Assumptions'!$A$1:$A$34,0),2) -> 0.0326 | I41: =F41*(1+G41)*(1+H41) -> 1.1512468e+08 | J41: =IF(I41>E41,"Y","") -> Y | K41: =IF(J41="",0,I41-E41) -> 2535581.5 | M41: =IF(L41="x",0,K41) -> 2535581.5 | N41: =M41+I41 -> 1.1766027e+08
A42: Pasadena | B42: =INDEX('Base Allocation'!$A$2:$AI$77,MATCH('District Specific SCFF'!$A42,'Base Allocation'!$A$2:$A$77,0),MATCH('District Specific SCFF'!B$1,'Base Allocation'!$A$2:$AI$2,0)) -> 1.0513312e+08 | C42: =INDEX('Supplemental Allocation'!$A$2:$Q$76,MATCH('District Specific SCFF'!$A42,'Supplemental Allocation'!$A$2:$A$76,0),MATCH('District Specific SCFF'!C$1,'Supplemental Allocation'!$A$2:$Q$2,0)) -> 28181737 | D42: =INDEX('Success Allocation'!$A$3:$EP$76,MATCH('District Specific SCFF'!$A42,'Success Allocation'!$A$3:$A$76,0),MATCH('District Specific SCFF'!D$1,'Success Allocation'!$A$3:$EP$3,0)) -> 18242406 | E42: =SUM(B42:D42) -> 1.5155727e+08 | F42: 134464486 | G42: =INDEX('Rate Assumptions'!$A$1:$C$34,MATCH('District Specific SCFF'!G$1,'Rate Assumptions'!$A$1:$A$34,0),2) -> 0.0271 | H42: =INDEX('Rate Assumptions'!$A$1:$C$34,MATCH('District Specific SCFF'!H$1,'Rate Assumptions'!$A$1:$A$34,0),2) -> 0.0326 | I42: =F42*(1+G42)*(1+H42) -> 1.4261081e+08 | J42: =IF(I42>E42,"Y","") | K42: =IF(J42="",0,I42-E42) -> 0 | M42: =IF(L42="x",0,K42) -> 0 | N42: =M42+I42 -> 1.4261081e+08
A43: Peralta | B43: =INDEX('Base Allocation'!$A$2:$AI$77,MATCH('District Specific SCFF'!$A43,'Base Allocation'!$A$2:$A$77,0),MATCH('District Specific SCFF'!B$1,'Base Allocation'!$A$2:$AI$2,0)) -> 88635367 | C43: =INDEX('Supplemental Allocation'!$A$2:$Q$76,MATCH('District Specific SCFF'!$A43,'Supplemental Allocation'!$A$2:$A$76,0),MATCH('District Specific SCFF'!C$1,'Supplemental Allocation'!$A$2:$Q$2,0)) -> 21486983 | D43: =INDEX('Success Allocation'!$A$3:$EP$76,MATCH('District Specific SCFF'!$A43,'Success Allocation'!$A$3:$A$76,0),MATCH('District Specific SCFF'!D$1,'Success Allocation'!$A$3:$EP$3,0)) -> 10982378 | E43: =SUM(B43:D43) -> 1.2110473e+08 | F43: 114674531 | G43: =INDEX('Rate Assumptions'!$A$1:$C$34,MATCH('District Specific SCFF'!G$1,'Rate Assumptions'!$A$1:$A$34,0),2) -> 0.0271 | H43: =INDEX('Rate Assumptions'!$A$1:$C$34,MATCH('District Specific SCFF'!H$1,'Rate Assumptions'!$A$1:$A$34,0),2) -> 0.0326 | I43: =F43*(1+G43)*(1+H43) -> 1.2162191e+08 | J43: =IF(I43>E43,"Y","") -> Y | K43: =IF(J43="",0,I43-E43) -> 517183.75 | M43: =IF(L43="x",0,K43) -> 517183.75 | N43: =M43+I43 -> 1.2213909e+08
A44: Rancho Santiago | B44: =INDEX('Base Allocation'!$A$2:$AI$77,MATCH('District Specific SCFF'!$A44,'Base Allocation'!$A$2:$A$77,0),MATCH('District Specific SCFF'!B$1,'Base Allocation'!$A$2:$AI$2,0)) -> 1.3747475e+08 | C44: =INDEX('Supplemental Allocation'!$A$2:$Q$76,MATCH('District Specific SCFF'!$A44,'Supplemental Allocation'!$A$2:$A$76,0),MATCH('District Specific SCFF'!C$1,'Supplemental Allocation'!$A$2:$Q$2,0)) -> 25960068 | D44: =INDEX('Success Allocation'!$A$3:$EP$76,MATCH('District Specific SCFF'!$A44,'Success Allocation'!$A$3:$A$76,0),MATCH('District Specific SCFF'!D$1,'Success Allocation'!$A$3:$EP$3,0)) -> 18254490 | E44: =SUM(B44:D44) -> 1.8168931e+08 | F44: 164850888 | G44: =INDEX('Rate Assumptions'!$A$1:$C$34,MATCH('District Specific SCFF'!G$1,'Rate Assumptions'!$A$1:$A$34,0),2) -> 0.0271 | H44: =INDEX('Rate Assumptions'!$A$1:$C$34,MATCH('District Specific SCFF'!H$1,'Rate Assumptions'!$A$1:$A$34,0),2) -> 0.0326 | I44: =F44*(1+G44)*(1+H44) -> 1.7483813e+08 | J44: =IF(I44>E44,"Y","") | K44: =IF(J44="",0,I44-E44) -> 0 | M44: =IF(L44="x",0,K44) -> 0 | N44: =M44+I44 -> 1.7483813e+08
A45: Redwoods | B45: =INDEX('Base Allocation'!$A$2:$AI$77,MATCH('District Specific SCFF'!$A45,'Base Allocation'!$A$2:$A$77,0),MATCH('District Specific SCFF'!B$1,'Base Allocation'!$A$2:$AI$2,0)) -> 21372499 | C45: =INDEX('Supplemental Allocation'!$A$2:$Q$76,MATCH('District Specific SCFF'!$A45,'Supplemental Allocation'!$A$2:$A$76,0),MATCH('District Specific SCFF'!C$1,'Supplemental Allocation'!$A$2:$Q$2,0)) -> 5192571.3 | D45: =INDEX('Success Allocation'!$A$3:$EP$76,MATCH('District Specific SCFF'!$A45,'Success Allocation'!$A$3:$A$76,0),MATCH('District Specific SCFF'!D$1,'Success Allocation'!$A$3:$EP$3,0)) -> 3212567.6 | E45: =SUM(B45:D45) -> 29777638 | F45: 26897607 | G45: =INDEX('Rate Assumptions'!$A$1:$C$34,MATCH('District Specific SCFF'!G$1,'Rate Assumptions'!$A$1:$A$34,0),2) -> 0.0271 | H45: =INDEX('Rate Assumptions'!$A$1:$C$34,MATCH('District Specific SCFF'!H$1,'Rate Assumptions'!$A$1:$A$34,0),2) -> 0.0326 | I45: =F45*(1+G45)*(1+H45) -> 28527157 | J45: =IF(I45>E45,"Y","") | K45: =IF(J45="",0,I45-E45) -> 0 | M45: =IF(L45="x",0,K45) -> 0 | N45: =M45+I45 -> 28527157
... A51: San Joaquin Delta | B51: =INDEX('Base Allocation'!$A$2:$AI$77,MATCH('District Specific SCFF'!$A51,'Base Allocation'!$A$2:$A$77,0),MATCH('District Specific SCFF'!B$1,'Base Allocation'!$A$2:$AI$2,0)) -> 68761467 | C51: =INDEX('Supplemental Allocation'!$A$2:$Q$76,MATCH('District Specific SCFF'!$A51,'Supplemental Allocation'!$A$2:$A$76,0),MATCH('District Specific SCFF'!C$1,'Supplemental Allocation'!$A$2:$Q$2,0)) -> 20877186 | D51: =INDEX('Success Allocation'!$A$3:$EP$76,MATCH('District Specific SCFF'!$A51,'Success Allocation'!$A$3:$A$76,0),MATCH('District Specific SCFF'!D$1,'Success Allocation'!$A$3:$EP$3,0)) -> 12389409 | E51: =SUM(B51:D51) -> 1.0202806e+08 | F51: 90280054 | G51: =INDEX('Rate Assumptions'!$A$1:$C$34,MATCH('District Specific SCFF'!G$1,'Rate Assumptions'!$A$1:$A$34,0),2) -> 0.0271 | H51: =INDEX('Rate Assumptions'!$A$1:$C$34,MATCH('District Specific SCFF'!H$1,'Rate Assumptions'!$A$1:$A$34,0),2) -> 0.0326 | I51: =F51*(1+G51)*(1+H51) -> 95749532 | J51: =IF(I51>E51,"Y","") | K51: =IF(J51="",0,I51-E51) -> 0 | M51: =IF(L51="x",0,K51) -> 0 | N51: =M51+I51 -> 95749532
A52: San Jose | B52: =INDEX('Base Allocation'!$A$2:$AI$77,MATCH('District Specific SCFF'!$A52,'Base Allocation'!$A$2:$A$77,0),MATCH('District Specific SCFF'!B$1,'Base Allocation'!$A$2:$AI$2,0)) -> 57509202 | C52: =INDEX('Supplemental Allocation'!$A$2:$Q$76,MATCH('District Specific SCFF'!$A52,'Supplemental Allocation'!$A$2:$A$76,0),MATCH('District Specific SCFF'!C$1,'Supplemental Allocation'!$A$2:$Q$2,0)) -> 15935598 | D52: =INDEX('Success Allocation'!$A$3:$EP$76,MATCH('District Specific SCFF'!$A52,'Success Allocation'!$A$3:$A$76,0),MATCH('District Specific SCFF'!D$1,'Success Allocation'!$A$3:$EP$3,0)) -> 8263072.7 | E52: =SUM(B52:D52) -> 81707872 | F52: 70622433 | G52: =INDEX('Rate Assumptions'!$A$1:$C$34,MATCH('District Specific SCFF'!G$1,'Rate Assumptions'!$A$1:$A$34,0),2) -> 0.0271 | H52: =INDEX('Rate Assumptions'!$A$1:$C$34,MATCH('District Specific SCFF'!H$1,'Rate Assumptions'!$A$1:$A$34,0),2) -> 0.0326 | I52: =F52*(1+G52)*(1+H52) -> 74900984 | J52: =IF(I52>E52,"Y","") | K52: =IF(J52="",0,I52-E52) -> 0 | L52: x | M52: =IF(L52="x",0,K52) -> 0 | N52: =M52+I52 -> 74900984
A53: San Luis Obispo | B53: =INDEX('Base Allocation'!$A$2:$AI$77,MATCH('District Specific SCFF'!$A53,'Base Allocation'!$A$2:$A$77,0),MATCH('District Specific SCFF'!B$1,'Base Allocation'!$A$2:$AI$2,0)) -> 38498095 | C53: =INDEX('Supplemental Allocation'!$A$2:$Q$76,MATCH('District Specific SCFF'!$A53,'Supplemental Allocation'!$A$2:$A$76,0),MATCH('District Specific SCFF'!C$1,'Supplemental Allocation'!$A$2:$Q$2,0)) -> 7995221.2 | D53: =INDEX('Success Allocation'!$A$3:$EP$76,MATCH('District Specific SCFF'!$A53,'Success Allocation'!$A$3:$A$76,0),MATCH('District Specific SCFF'!D$1,'Success Allocation'!$A$3:$EP$3,0)) -> 6017921.3 | E53: =SUM(B53:D53) -> 52511237 | F53: 49069768 | G53: =INDEX('Rate Assumptions'!$A$1:$C$34,MATCH('District Specific SCFF'!G$1,'Rate Assumptions'!$A$1:$A$34,0),2) -> 0.0271 | H53: =INDEX('Rate Assumptions'!$A$1:$C$34,MATCH('District Specific SCFF'!H$1,'Rate Assumptions'!$A$1:$A$34,0),2) -> 0.0326 | I53: =F53*(1+G53)*(1+H53) -> 52042584 | J53: =IF(I53>E53,"Y","") | K53: =IF(J53="",0,I53-E53) -> 0 | M53: =IF(L53="x",0,K53) -> 0 | N53: =M53+I53 -> 52042584
A54: San Mateo | B54: =INDEX('Base Allocation'!$A$2:$AI$77,MATCH('District Specific SCFF'!$A54,'Base Allocation'!$A$2:$A$77,0),MATCH('District Specific SCFF'!B$1,'Base Allocation'!$A$2:$AI$2,0)) -> 74755545 | C54: =INDEX('Supplemental Allocation'!$A$2:$Q$76,MATCH('District Specific SCFF'!$A54,'Supplemental Allocation'!$A$2:$A$76,0),MATCH('District Specific SCFF'!C$1,'Supplemental Allocation'!$A$2:$Q$2,0)) -> 13788294 | D54: =INDEX('Success Allocation'!$A$3:$EP$76,MATCH('District Specific SCFF'!$A54,'Success Allocation'!$A$3:$A$76,0),MATCH('District Specific SCFF'!D$1,'Success Allocation'!$A$3:$EP$3,0)) -> 11450122 | E54: =SUM(B54:D54) -> 99993961 | F54: 98289606 | G54: =INDEX('Rate Assumptions'!$A$1:$C$34,MATCH('District Specific SCFF'!G$1,'Rate Assumptions'!$A$1:$A$34,0),2) -> 0.0271 | H54: =INDEX('Rate Assumptions'!$A$1:$C$34,MATCH('District Specific SCFF'!H$1,'Rate Assumptions'!$A$1:$A$34,0),2) -> 0.0326 | I54: =F54*(1+G54)*(1+H54) -> 1.0424433e+08 | J54: =IF(I54>E54,"Y","") -> Y | K54: =IF(J54="",0,I54-E54) -> 4250369.3 | L54: x | M54: =IF(L54="x",0,K54) -> 0 | N54: =M54+I54 -> 1.0424433e+08
A55: Santa Barbara | B55: =INDEX('Base Allocation'!$A$2:$AI$77,MATCH('District Specific SCFF'!$A55,'Base Allocation'!$A$2:$A$77,0),MATCH('District Specific SCFF'!B$1,'Base Allocation'!$A$2:$AI$2,0)) -> 57719268 | C55: =INDEX('Supplemental Allocation'!$A$2:$Q$76,MATCH('District Specific SCFF'!$A55,'Supplemental Allocation'!$A$2:$A$76,0),MATCH('District Specific SCFF'!C$1,'Supplemental Allocation'!$A$2:$Q$2,0)) -> 12488757 | D55: =INDEX('Success Allocation'!$A$3:$EP$76,MATCH('District Specific SCFF'!$A55,'Success Allocation'!$A$3:$A$76,0),MATCH('District Specific SCFF'!D$1,'Success Allocation'!$A$3:$EP$3,0)) -> 8504950.7 | E55: =SUM(B55:D55) -> 78712975 | F55: 72610515 | G55: =INDEX('Rate Assumptions'!$A$1:$C$34,MATCH('District Specific SCFF'!G$1,'Rate Assumptions'!$A$1:$A$34,0),2) -> 0.0271 | H55: =INDEX('Rate Assumptions'!$A$1:$C$34,MATCH('District Specific SCFF'!H$1,'Rate Assumptions'!$A$1:$A$34,0),2) -> 0.0326 | I55: =F55*(1+G55)*(1+H55) -> 77009511 | J55: =IF(I55>E55,"Y","") | K55: =IF(J55="",0,I55-E55) -> 0 | M55: =IF(L55="x",0,K55) -> 0 | N55: =M55+I55 -> 77009511
A56: Santa Clarita | B56: =INDEX('Base Allocation'!$A$2:$AI$77,MATCH('District Specific SCFF'!$A56,'Base Allocation'!$A$2:$A$77,0),MATCH('District Specific SCFF'!B$1,'Base Allocation'!$A$2:$AI$2,0)) -> 72979666 | C56: =INDEX('Supplemental Allocation'!$A$2:$Q$76,MATCH('District Specific SCFF'!$A56,'Supplemental Allocation'!$A$2:$A$76,0),MATCH('District Specific SCFF'!C$1,'Supplemental Allocation'!$A$2:$Q$2,0)) -> 13614465 | D56: =INDEX('Success Allocation'!$A$3:$EP$76,MATCH('District Specific SCFF'!$A56,'Success Allocation'!$A$3:$A$76,0),MATCH('District Specific SCFF'!D$1,'Success Allocation'!$A$3:$EP$3,0)) -> 13564937 | E56: =SUM(B56:D56) -> 1.0015907e+08 | F56: 94448588 | G56: =INDEX('Rate Assumptions'!$A$1:$C$34,MATCH('District Specific SCFF'!G$1,'Rate Assumptions'!$A$1:$A$34,0),2) -> 0.0271 | H56: =INDEX('Rate Assumptions'!$A$1:$C$34,MATCH('District Specific SCFF'!H$1,'Rate Assumptions'!$A$1:$A$34,0),2) -> 0.0326 | I56: =F56*(1+G56)*(1+H56) -> 1.0017061e+08 | J56: =IF(I56>E56,"Y","") -> Y | K56: =IF(J56="",0,I56-E56) -> 11542.655 | M56: =IF(L56="x",0,K56) -> 11542.655 | N56: =M56+I56 -> 1.0018215e+08
A57: Santa Monica | B57: =INDEX('Base Allocation'!$A$2:$AI$77,MATCH('District Specific SCFF'!$A57,'Base Allocation'!$A$2:$A$77,0),MATCH('District Specific SCFF'!B$1,'Base Allocation'!$A$2:$AI$2,0)) -> 86857394 | C57: =INDEX('Supplemental Allocation'!$A$2:$Q$76,MATCH('District Specific SCFF'!$A57,'Supplemental Allocation'!$A$2:$A$76,0),MATCH('District Specific SCFF'!C$1,'Supplemental Allocation'!$A$2:$Q$2,0)) -> 26195249 | D57: =INDEX('Success Allocation'!$A$3:$EP$76,MATCH('District Specific SCFF'!$A57,'Success Allocation'!$A$3:$A$76,0),MATCH('District Specific SCFF'!D$1,'Success Allocation'!$A$3:$EP$3,0)) -> 15569122 | E57: =SUM(B57:D57) -> 1.2862177e+08 | F57: 129918589 | G57: =INDEX('Rate Assumptions'!$A$1:$C$34,MATCH('District Specific SCFF'!G$1,'Rate Assumptions'!$A$1:$A$34,0),2) -> 0.0271 | H57: =INDEX('Rate Assumptions'!$A$1:$C$34,MATCH('District Specific SCFF'!H$1,'Rate Assumptions'!$A$1:$A$34,0),2) -> 0.0326 | I57: =F57*(1+G57)*(1+H57) -> 1.3778951e+08 | J57: =IF(I57>E57,"Y","") -> Y | K57: =IF(J57="",0,I57-E57) -> 9167741 | M57: =IF(L57="x",0,K57) -> 9167741 | N57: =M57+I57 -> 1.4695725e+08
A58: Sequoias | B58: =INDEX('Base Allocation'!$A$2:$AI$77,MATCH('District Specific SCFF'!$A58,'Base Allocation'!$A$2:$A$77,0),MATCH('District Specific SCFF'!B$1,'Base Allocation'!$A$2:$AI$2,0)) -> 49432270 | C58: =INDEX('Supplemental Allocation'!$A$2:$Q$76,MATCH('District Specific SCFF'!$A58,'Supplemental Allocation'!$A$2:$A$76,0),MATCH('District Specific SCFF'!C$1,'Supplemental Allocation'!$A$2:$Q$2,0)) -> 15945823 | D58: =INDEX('Success Allocation'!$A$3:$EP$76,MATCH('District Specific SCFF'!$A58,'Success Allocation'!$A$3:$A$76,0),MATCH('District Specific SCFF'!D$1,'Success Allocation'!$A$3:$EP$3,0)) -> 8290263.6 | E58: =SUM(B58:D58) -> 73668356 | F58: 61392655 | G58: =INDEX('Rate Assumptions'!$A$1:$C$34,MATCH('District Specific SCFF'!G$1,'Rate Assumptions'!$A$1:$A$34,0),2) -> 0.0271 | H58: =INDEX('Rate Assumptions'!$A$1:$C$34,MATCH('District Specific SCFF'!H$1,'Rate Assumptions'!$A$1:$A$34,0),2) -> 0.0326 | I58: =F58*(1+G58)*(1+H58) -> 65112034 | J58: =IF(I58>E58,"Y","") | K58: =IF(J58="",0,I58-E58) -> 0 | M58: =IF(L58="x",0,K58) -> 0 | N58: =M58+I58 -> 65112034
A59: Shasta Tehama | B59: =INDEX('Base Allocation'!$A$2:$AI$77,MATCH('District Specific SCFF'!$A59,'Base Allocation'!$A$2:$A$77,0),MATCH('District Specific SCFF'!B$1,'Base Allocation'!$A$2:$AI$2,0)) -> 33210665 | C59: =INDEX('Supplemental Allocation'!$A$2:$Q$76,MATCH('District Specific SCFF'!$A59,'Supplemental Allocation'!$A$2:$A$76,0),MATCH('District Specific SCFF'!C$1,'Supplemental Allocation'!$A$2:$Q$2,0)) -> 12161549 | D59: =INDEX('Success Allocation'!$A$3:$EP$76,MATCH('District Specific SCFF'!$A59,'Success Allocation'!$A$3:$A$76,0),MATCH('District Specific SCFF'!D$1,'Success Allocation'!$A$3:$EP$3,0)) -> 6562690.4 | E59: =SUM(B59:D59) -> 51934904 | F59: 41789199 | G59: =INDEX('Rate Assumptions'!$A$1:$C$34,MATCH('District Specific SCFF'!G$1,'Rate Assumptions'!$A$1:$A$34,0),2) -> 0.0271 | H59: =INDEX('Rate Assumptions'!$A$1:$C$34,MATCH('District Specific SCFF'!H$1,'Rate Assumptions'!$A$1:$A$34,0),2) -> 0.0326 | I59: =F59*(1+G59)*(1+H59) -> 44320933 | J59: =IF(I59>E59,"Y","") | K59: =IF(J59="",0,I59-E59) -> 0 | M59: =IF(L59="x",0,K59) -> 0 | N59: =M59+I59 -> 44320933
A60: Sierra | B60: =INDEX('Base Allocation'!$A$2:$AI$77,MATCH('District Specific SCFF'!$A60,'Base Allocation'!$A$2:$A$77,0),MATCH('District Specific SCFF'!B$1,'Base Allocation'!$A$2:$AI$2,0)) -> 61536862 | C60: =INDEX('Supplemental Allocation'!$A$2:$Q$76,MATCH('District Specific SCFF'!$A60,'Supplemental Allocation'!$A$2:$A$76,0),MATCH('District Specific SCFF'!C$1,'Supplemental Allocation'!$A$2:$Q$2,0)) -> 16685760 | D60: =INDEX('Success Allocation'!$A$3:$EP$76,MATCH('District Specific SCFF'!$A60,'Success Allocation'!$A$3:$A$76,0),MATCH('District Specific SCFF'!D$1,'Success Allocation'!$A$3:$EP$3,0)) -> 12048574 | E60: =SUM(B60:D60) -> 90271196 | F60: 86569715 | G60: =INDEX('Rate Assumptions'!$A$1:$C$34,MATCH('District Specific SCFF'!G$1,'Rate Assumptions'!$A$1:$A$34,0),2) -> 0.0271 | H60: =INDEX('Rate Assumptions'!$A$1:$C$34,MATCH('District Specific SCFF'!H$1,'Rate Assumptions'!$A$1:$A$34,0),2) -> 0.0326 | I60: =F60*(1+G60)*(1+H60) -> 91814408 | J60: =IF(I60>E60,"Y","") -> Y | K60: =IF(J60="",0,I60-E60) -> 1543212.1 | M60: =IF(L60="x",0,K60) -> 1543212.1 | N60: =M60+I60 -> 93357620
...

Sheet Base Allocation
B1: 2016-17 | H1: 2017-18 | N1: 2018-19 | T1: 2019-20 Projection | Z1: Model Inputs | AE1: Rates
A2: FTES Data | B2: FTES | E2: Inmates in Correctional Facilities Education FTES | F2: Special Admit FTES | G2: Excluding Inmates and Special Admit | H2: FTES | K2: Inmates in Correctional Facilities Education FTES | L2: Special Admit FTES | M2: Excluding Inmates and Special Admit | N2: FTES | Q2: Inmates in Correctional Facilities Education FTES | R2: Special Admit FTES | S2: Excluding Inmates and Special Admit | T2: FTES | W2: Inmates in Correctional Facilities Education FTES | X2: Special Admit FTES | Y2: Excluding Inmates and Special Admit | Z2: 3-Year Average Credit FTES (Excluding Inmates and Special Admits) | AA2: Noncredit FTES | AB2: CDCP FTES | AC2: Special Admits and Students in Correctional Facilities FTES | AD2: Basic Allocation DOF | AE2: Credit FTES | AF2: Noncredit FTES | AG2: CDCP FTES | AH2: Special Admits and Students in Correctional Facilities FTES | AI2: Base Allocation
B3: Credit | C3: Noncredit | D3: CDCP | E3: Credit | F3: Credit | G3: Credit | H3: Credit | I3: Noncredit | J3: CDCP | K3: Credit | L3: Credit | M3: Credit | N3: Credit | O3: Noncredit | P3: CDCP | Q3: Credit | R3: Credit | S3: Credit | T3: Credit | U3: Noncredit | V3: CDCP | W3: Credit | X3: Credit | Y3: Credit
A4: District
A5: Allan Hancock | B5: 9202.61 | C5: 499.92 | D5: 319.04 | E5: 106.5 | F5: 425.76 | G5: =B5-E5-F5 -> 8670.35 | H5: 7860.16 | I5: 431.7 | J5: 261.7 | K5: 83.47 | L5: 436.82 | M5: =H5-K5-L5 -> 7339.87 | N5: 8984.08 | O5: 401.82 | P5: 255.44 | Q5: 73.67 | R5: 420.1 | S5: =N5-Q5-R5 -> 8490.31 | T5: =IF((H5-B5)*(1/3)+(N5-H5)*(2/3) + N5>0,N5+(H5-B5)*(1/3)+(N5-H5)*(2/3),N5) -> 9285.8767 | U5: =IF((I5-C5)*(1/3)+(O5-I5)*(2/3) + O5>0,O5+(I5-C5)*(1/3)+(O5-I5)*(2/3),O5) -> 359.16 | V5: =IF((J5-D5)*(1/3)+(P5-J5)*(2/3) + P5>0,P5+(J5-D5)*(1/3)+(P5-J5)*(2/3),P5) -> 232.15333 | W5: =IF((K5-E5)*(1/3)+(Q5-K5)*(2/3) + Q5>0,Q5+(K5-E5)*(1/3)+(Q5-K5)*(2/3),Q5) -> 59.46 | X5: =IF((L5-F5)*(1/3)+(R5-L5)*(2/3) + R5>0,R5+(L5-F5)*(1/3)+(R5-L5)*(2/3),R5) -> 412.64 | Y5: =T5-W5-X5 -> 8813.7767 | Z5: =AVERAGE(Y5,S5,M5) -> 8214.6522 | AA5: =U5 -> 359.16 | AB5: =V5 -> 232.15333 | AC5: =SUM(W5:X5) -> 472.1 | AD5: 6742470.1 | AE5: =INDEX('Rate Assumptions'!$A:$B,MATCH('Base Allocation'!AE$2,'Rate Assumptions'!$A:$A,0),2) -> 3988.5862 | AF5: =INDEX('Rate Assumptions'!$A:$B,MATCH('Base Allocation'!AF$2,'Rate Assumptions'!$A:$A,0),2) -> 3456.4415 | AG5: =INDEX('Rate Assumptions'!$A:$B,MATCH('Base Allocation'!AG$2,'Rate Assumptions'!$A:$A,0),2) -> 5634.5606 | AH5: =INDEX('Rate Assumptions'!$A:$B,MATCH('Base Allocation'!AH$2,'Rate Assumptions'!$A:$A,0),2) -> 5634.5606 | AI5: =AD5+SUMPRODUCT(Z5:AC5,AE5:AH5) -> 44716892
A6: Antelope | B6: 10523.45 | C6: 4.5 | D6: 39.28 | E6: 8.68 | F6: 302.6 | G6: =B6-E6-F6 -> 10212.17 | H6: 10527.04 | I6: 7.919966 | J6: 80.880058 | K6: 1.79 | L6: 308.01 | M6: =H6-K6-L6 -> 10217.24 | N6: 10968.8 | O6: 7.61 | P6: 55.1 | Q6: 11.01 | R6: 341.84 | S6: =N6-Q6-R6 -> 10615.95 | T6: =IF((H6-B6)*(1/3)+(N6-H6)*(2/3) + N6>0,N6+(H6-B6)*(1/3)+(N6-H6)*(2/3),N6) -> 11264.503 | U6: =IF((I6-C6)*(1/3)+(O6-I6)*(2/3) + O6>0,O6+(I6-C6)*(1/3)+(O6-I6)*(2/3),O6) -> 8.5433447 | V6: =IF((J6-D6)*(1/3)+(P6-J6)*(2/3) + P6>0,P6+(J6-D6)*(1/3)+(P6-J6)*(2/3),P6) -> 51.779981 | W6: =IF((K6-E6)*(1/3)+(Q6-K6)*(2/3) + Q6>0,Q6+(K6-E6)*(1/3)+(Q6-K6)*(2/3),Q6) -> 14.86 | X6: =IF((L6-F6)*(1/3)+(R6-L6)*(2/3) + R6>0,R6+(L6-F6)*(1/3)+(R6-L6)*(2/3),R6) -> 366.19667 | Y6: =T6-W6-X6 -> 10883.447 | Z6: =AVERAGE(Y6,S6,M6) -> 10572.212 | AA6: =U6 -> 8.5433447 | AB6: =V6 -> 51.779981 | AC6: =SUM(W6:X6) -> 381.05667 | AD6: 6742470.1 | AE6: =INDEX('Rate Assumptions'!$A:$B,MATCH('Base Allocation'!AE$2,'Rate Assumptions'!$A:$A,0),2) -> 3988.5862 | AF6: =INDEX('Rate Assumptions'!$A:$B,MATCH('Base Allocation'!AF$2,'Rate Assumptions'!$A:$A,0),2) -> 3456.4415 | AG6: =INDEX('Rate Assumptions'!$A:$B,MATCH('Base Allocation'!AG$2,'Rate Assumptions'!$A:$A,0),2) -> 5634.5606 | AH6: =INDEX('Rate Assumptions'!$A:$B,MATCH('Base Allocation'!AH$2,'Rate Assumptions'!$A:$A,0),2) -> 5634.5606 | AI6: =AD6+SUMPRODUCT(Z6:AC6,AE6:AH6) -> 51379024
A7: Barstow | B7: 2565.1499 | C7: 17.72 | D7: 0 | F7: 39.21 | G7: =B7-E7-F7 -> 2525.9399 | H7: 2320.71 | I7: 29.82 | J7: 0 | L7: 43.74 | M7: =H7-K7-L7 -> 2276.97 | N7: 2552.27 | O7: 29.84 | P7: 0 | Q7: 0 | R7: 0 | S7: =N7-Q7-R7 -> 2552.27 | T7: =IF((H7-B7)*(1/3)+(N7-H7)*(2/3) + N7>0,N7+(H7-B7)*(1/3)+(N7-H7)*(2/3),N7) -> 2625.1634 | U7: =IF((I7-C7)*(1/3)+(O7-I7)*(2/3) + O7>0,O7+(I7-C7)*(1/3)+(O7-I7)*(2/3),O7) -> 33.886667 | V7: =IF((J7-D7)*(1/3)+(P7-J7)*(2/3) + P7>0,P7+(J7-D7)*(1/3)+(P7-J7)*(2/3),P7) -> 0 | W7: =IF((K7-E7)*(1/3)+(Q7-K7)*(2/3) + Q7>0,Q7+(K7-E7)*(1/3)+(Q7-K7)*(2/3),Q7) -> 0 | X7: =IF((L7-F7)*(1/3)+(R7-L7)*(2/3) + R7>0,R7+(L7-F7)*(1/3)+(R7-L7)*(2/3),R7) -> 0 | Y7: =T7-W7-X7 -> 2625.1634 | Z7: =AVERAGE(Y7,S7,M7) -> 2484.8011 | AA7: =U7 -> 33.886667 | AB7: =V7 -> 0 | AC7: =SUM(W7:X7) -> 0 | AD7: 5332192.5 | AE7: =INDEX('Rate Assumptions'!$A:$B,MATCH('Base Allocation'!AE$2,'Rate Assumptions'!$A:$A,0),2) -> 3988.5862 | AF7: =INDEX('Rate Assumptions'!$A:$B,MATCH('Base Allocation'!AF$2,'Rate Assumptions'!$A:$A,0),2) -> 3456.4415 | AG7: =INDEX('Rate Assumptions'!$A:$B,MATCH('Base Allocation'!AG$2,'Rate Assumptions'!$A:$A,0),2) -> 5634.5606 | AH7: =INDEX('Rate Assumptions'!$A:$B,MATCH('Base Allocation'!AH$2,'Rate Assumptions'!$A:$A,0),2) -> 5634.5606 | AI7: =AD7+SUMPRODUCT(Z7:AC7,AE7:AH7) -> 15360163
A8: Butte | B8: 8717.92 | C8: 1245.24 | D8: 23.44 | F8: 172.12 | G8: =B8-E8-F8 -> 8545.8 | H8: 9162.4001 | I8: 1195.77 | J8: 25.05 | L8: 185.72 | M8: =H8-K8-L8 -> 8976.6801 | N8: 9162.4 | O8: 1195.77 | P8: 25.05 | Q8: 0 | R8: 185.72 | S8: =N8-Q8-R8 -> 8976.68 | T8: =IF((H8-B8)*(1/3)+(N8-H8)*(2/3) + N8>0,N8+(H8-B8)*(1/3)+(N8-H8)*(2/3),N8) -> 9310.56 | U8: =IF((I8-C8)*(1/3)+(O8-I8)*(2/3) + O8>0,O8+(I8-C8)*(1/3)+(O8-I8)*(2/3),O8) -> 1179.28 | V8: =IF((J8-D8)*(1/3)+(P8-J8)*(2/3) + P8>0,P8+(J8-D8)*(1/3)+(P8-J8)*(2/3),P8) -> 25.586667 | W8: =IF((K8-E8)*(1/3)+(Q8-K8)*(2/3) + Q8>0,Q8+(K8-E8)*(1/3)+(Q8-K8)*(2/3),Q8) -> 0 | X8: =IF((L8-F8)*(1/3)+(R8-L8)*(2/3) + R8>0,R8+(L8-F8)*(1/3)+(R8-L8)*(2/3),R8) -> 190.25333 | Y8: =T8-W8-X8 -> 9120.3066 | Z8: =AVERAGE(Y8,S8,M8) -> 9024.5556 | AA8: =U8 -> 1179.28 | AB8: =V8 -> 25.586667 | AC8: =SUM(W8:X8) -> 190.25333 | AD8: 6742470.1 | AE8: =INDEX('Rate Assumptions'!$A:$B,MATCH('Base Allocation'!AE$2,'Rate Assumptions'!$A:$A,0),2) -> 3988.5862 | AF8: =INDEX('Rate Assumptions'!$A:$B,MATCH('Base Allocation'!AF$2,'Rate Assumptions'!$A:$A,0),2) -> 3456.4415 | AG8: =INDEX('Rate Assumptions'!$A:$B,MATCH('Base Allocation'!AG$2,'Rate Assumptions'!$A:$A,0),2) -> 5634.5606 | AH8: =INDEX('Rate Assumptions'!$A:$B,MATCH('Base Allocation'!AH$2,'Rate Assumptions'!$A:$A,0),2) -> 5634.5606 | AI8: =AD8+SUMPRODUCT(Z8:AC8,AE8:AH8) -> 48029964
